Workbook

Sheet Read Me
A1: University economics: production backlog (100 videos)
A2: Built 2026-10-22 from open textbooks and the economics channel scan (162 channels, 23,741 videos).
A4: Courses and sources
A5: MI = Intermediate Microeconomics (30): McAfee & Lewis, Introduction to Economic Analysis (CC BY-NC-SA, free PDF).
A6: MA = Intermediate Macroeconomics (26): Garín, Lester & Sims, Intermediate Macroeconomics (free PDF from the authors).
A7: GT = Game Theory (14): Bonanno, Game Theory (open access, UC Davis).
A8: EC = Econometrics (26): Hanck et al., Introduction to Econometrics with R (CC BY-NC-SA); Huntington-Klein, The Effect (free online); Cunningham, Causal Inference: The Mixtape (free online).
A9: XC = cross-course format experiments (4): the full-degree compression, a 5-levels video, a history-of-an-idea video, and the IB diagrams anchor.
A11: Columns
A12: Format: Explainer (model/concept, 8-15 min) / Worked problem ("how to solve X", the format the stale incumbents own) / Anchor ("ALL of…" compression, made after the course's explainers exist).
A13: Exam tag: which exam audiences the topic also serves (IB, A-level, AP) so titles and descriptions can carry the board name; "University" = intermediate-level only.
A14: Demand signal: High = at least 3 small-channel outlier videos (or one at 5x+ its channel) on the raw test AND an age-adjusted signal; Medium = one of the two; Low = comparable videos exist but none outperform; "No comparable video" = nothing in the scan matched.
... A20: Status and Publish date (yellow) are yours to edit; the Progress tab counts them.

Sheet Backlog
A1: Order | B1: Week | C1: Phase | D1: Code | E1: Course | F1: Source section (textbook) | G1: Working title | H1: Format | I1: Target length | J1: Prerequisites | K1: Exam tag | L1: Demand signal | M1: Supply age | N1: Videos found in scan | O1: Channels covering | P1: Small-ch outliers (raw) | Q1: Small-ch outliers (age-adj) | R1: Best small-ch Views/Subs | S1: Best small-ch Views/yr/Subs | T1: Median outlier age (yrs) | U1: Best evidence: video | V1: Evidence channel | W1: Evidence subs | X1: Evidence views | Y1: Views / Subs | Z1: Evidence age (yrs) | AA1: Evidence URL | AB1: Status | AC1: Publish date | AD1: Notes | AE1: Pending rank (helper)
A2: 1 | B2: =ROUNDUP(A2/3,0) -> 1 | C2: Phase 1: intermediate micro + macro, textbook order | D2: MI-01 | E2: Intermediate Microeconomics | F2: McAfee & Lewis, Introduction to Economic Analysis (CC BY-NC-SA) §2 Supply and Demand | G2: Supply and demand, properly: what shifts a curve and what moves along it | H2: Explainer | I2: 8-10 min | J2: None | K2: IB/A-level/AP | L2: High | M2: Stale (median outlier age 8y+) | N2: 71 | O2: 31 | P2: 16 | Q2: 4 | R2: 22.71 | S2: 1.62 | T2: 8 | U2: Supply and Demand (and Equilibrium Price & Quanitity) - Intro to Microeconomics | V2: economicurtis | W2: 36200 | X2: 822000 | Y2: =IF(OR(W2="",W2=0,X2=""),"",X2/W2) -> 22.707182 | Z2: 14 | AA2: https://youtu.be/op70yS_7du8 | AB2: Planned | AE2: =IF(AB2<>"Published",COUNTIF($AB$2:AB2,"<>Published"),"") -> 1
A3: 2 | B3: =ROUNDUP(A3/3,0) -> 1 | C3: Phase 1: intermediate micro + macro, textbook order | D3: MA-01 | E3: Intermediate Macroeconomics | F3: Garín, Lester & Sims, Intermediate Macroeconomics (free PDF) Ch.1-2 Measurement | G3: GDP, properly: three ways to measure one number | H3: Explainer | I3: 8-10 min | J3: None | K3: IB/A-level/AP | L3: High | M3: Ageing (4-8y) | N3: 21 | O3: 15 | P3: 4 | Q3: 0 | R3: 7.22 | S3: 1.61 | T3: 6 | U3: Three methods of GDP Calculation | V3: ecopoint | W3: 29500 | X3: 213000 | Y3: =IF(OR(W3="",W3=0,X3=""),"",X3/W3) -> 7.220339 | Z3: 14 | AA3: https://youtu.be/mgtVQQALWQI | AB3: Planned | AE3: =IF(AB3<>"Published",COUNTIF($AB$2:AB3,"<>Published"),"") -> 2
A4: 3 | B4: =ROUNDUP(A4/3,0) -> 1 | C4: Phase 1: intermediate micro + macro, textbook order | D4: MI-02 | E4: Intermediate Microeconomics | F4: McAfee & Lewis, Introduction to Economic Analysis (CC BY-NC-SA) §2.3 Elasticity | G4: How to solve elasticity problems (point, arc, revenue test) | H4: Worked problem ("how to solve") | I4: 8-10 min | J4: MI-01 | K4: IB/A-level/AP | L4: High | M4: Stale (median outlier age 8y+) | N4: 191 | O4: 38 | P4: 25 | Q4: 6 | R4: 27.88 | S4: 8.12 | T4: 9 | U4: How to Solve Elasticity Problems in Economics | V4: Free Econ Help | W4: 38300 | X4: 603000 | Y4: =IF(OR(W4="",W4=0,X4=""),"",X4/W4) -> 15.744125 | Z4: 15 | AA4: https://youtu.be/-2xh2Fz_XNo | AB4: Planned | AE4: =IF(AB4<>"Published",COUNTIF($AB$2:AB4,"<>Published"),"") -> 3
A5: 4 | B5: =ROUNDUP(A5/3,0) -> 2 | C5: Phase 1: intermediate micro + macro, textbook order | D5: MA-02 | E5: Intermediate Macroeconomics | F5: Garín, Lester & Sims, Intermediate Macroeconomics (free PDF) Ch.2 Prices | G5: Inflation, the CPI and the GDP deflator (and why they disagree) | H5: Explainer | I5: 8-10 min | J5: MA-01 | K5: IB/A-level/AP | L5: High | M5: Stale (median outlier age 8y+) | N5: 64 | O5: 37 | P5: 8 | Q5: 0 | R5: 5.29 | S5: 2.51 | T5: 8 | U5: How to Calculate the Consumer Price Index (CPI) and Inflation Rate | V5: Economics in Many Lessons | W5: 82800 | X5: 400000 | Y5: =IF(OR(W5="",W5=0,X5=""),"",X5/W5) -> 4.8309179 | Z5: 7 | AA5: https://youtu.be/6xJe_oJybDs | AB5: Planned | AE5: =IF(AB5<>"Published",COUNTIF($AB$2:AB5,"<>Published"),"") -> 4
A6: 5 | B6: =ROUNDUP(A6/3,0) -> 2 | C6: Phase 1: intermediate micro + macro, textbook order | D6: MI-03 | E6: Intermediate Microeconomics | F6: McAfee & Lewis, Introduction to Economic Analysis (CC BY-NC-SA) §2.1 Opportunity cost / PPF | G6: How to calculate opportunity cost (and why the PPF is curved) | H6: Worked problem ("how to solve") | I6: 6-8 min | J6: None | K6: IB/A-level/AP | L6: High | M6: Stale (median outlier age 8y+) | N6: 108 | O6: 35 | P6: 25 | Q6: 3 | R6: 23.84 | S6: 2.18 | T6: 10 | U6: How to calculate opportunity costs | V6: Free Econ Help | W6: 38300 | X6: 913000 | Y6: =IF(OR(W6="",W6=0,X6=""),"",X6/W6) -> 23.83812 | Z6: 14 | AA6: https://youtu.be/VZrNbHCkv6A | AB6: Planned | AE6: =IF(AB6<>"Published",COUNTIF($AB$2:AB6,"<>Published"),"") -> 5
A7: 6 | B7: =ROUNDUP(A7/3,0) -> 2 | C7: Phase 1: intermediate micro + macro, textbook order | D7: MA-03 | E7: Intermediate Macroeconomics | F7: Garín, Lester & Sims, Intermediate Macroeconomics (free PDF) Ch.4 Production function | G7: The aggregate production function and diminishing returns to capital | H7: Explainer | I7: 8-10 min | J7: MI-11 | K7: University | L7: Low | M7: - | N7: 6 | O7: 6 | P7: 0 | Q7: 0 | R7: 0.68 | S7: 0.11 | U7: What are diminishing returns in economics | V7: Free Econ Help | W7: 38300 | X7: 26000 | Y7: =IF(OR(W7="",W7=0,X7=""),"",X7/W7) -> 0.67885117 | Z7: 14 | AA7: https://youtu.be/QVlb4ciaKyA | AB7: Planned | AE7: =IF(AB7<>"Published",COUNTIF($AB$2:AB7,"<>Published"),"") -> 6
A8: 7 | B8: =ROUNDUP(A8/3,0) -> 3 | C8: Phase 1: intermediate micro + macro, textbook order | D8: MI-04 | E8: Intermediate Microeconomics | F8: McAfee & Lewis, Introduction to Economic Analysis (CC BY-NC-SA) §2.5 Surplus | G8: Consumer and producer surplus: how to calculate them from a graph | H8: Worked problem ("how to solve") | I8: 6-8 min | J8: MI-01 | K8: IB/A-level/AP | L8: High | M8: Stale (median outlier age 8y+) | N8: 68 | O8: 24 | P8: 14 | Q8: 1 | R8: 13.11 | S8: 1.57 | T8: 12 | U8: How to Calculate Consumer Surplus | V8: Free Econ Help | W8: 38300 | X8: 502000 | Y8: =IF(OR(W8="",W8=0,X8=""),"",X8/W8) -> 13.10705 | Z8: 15 | AA8: https://youtu.be/0hBIwRqTwmY | AB8: Planned | AE8: =IF(AB8<>"Published",COUNTIF($AB$2:AB8,"<>Published"),"") -> 7
A9: 8 | B9: =ROUNDUP(A9/3,0) -> 3 | C9: Phase 1: intermediate micro + macro, textbook order | D9: MA-04 | E9: Intermediate Macroeconomics | F9: Garín, Lester & Sims, Intermediate Macroeconomics (free PDF) Ch.5 Solow model | G9: The Solow growth model, part 1: the diagram and the steady state | H9: Explainer | I9: 12-15 min | J9: MA-03 | K9: University | L9: High | M9: Stale (median outlier age 8y+) | N9: 61 | O9: 12 | P9: 26 | Q9: 3 | R9: 33.53 | S9: 5.59 | T9: 13 | U9: Solow Growth Model | Part 1 | Model Intro & Solution | Intermediate Macroeconomics | V9: Tactical Economics | W9: 3370 | X9: 113000 | Y9: =IF(OR(W9="",W9=0,X9=""),"",X9/W9) -> 33.531157 | Z9: 6 | AA9: https://youtu.be/aywhE3BpJOs | AB9: Planned | AE9: =IF(AB9<>"Published",COUNTIF($AB$2:AB9,"<>Published"),"") -> 8
A10: 9 | B10: =ROUNDUP(A10/3,0) -> 3 | C10: Phase 1: intermediate micro + macro, textbook order | D10: MI-05 | E10: Intermediate Microeconomics | F10: McAfee & Lewis, Introduction to Economic Analysis (CC BY-NC-SA) §5 Government interventions | G10: Price ceilings, floors and taxes: who really pays? | H10: Explainer | I10: 8-10 min | J10: MI-04 | K10: IB/A-level | L10: Medium | M10: Stale (median outlier age 8y+) | N10: 44 | O10: 21 | P10: 5 | Q10: 0 | R10: 3.3 | S10: 0.81 | T10: 8 | U10: Price Ceiling and Price Floor | Think Econ | V10: Think Econ | W10: 77800 | X10: 252000 | Y10: =IF(OR(W10="",W10=0,X10=""),"",X10/W10) -> 3.2390746 | Z10: 4 | AA10: https://youtu.be/a2iKaTqgrxs | AB10: Planned | AE10: =IF(AB10<>"Published",COUNTIF($AB$2:AB10,"<>Published"),"") -> 9
A11: 10 | B11: =ROUNDUP(A11/3,0) -> 4 | C11: Phase 1: intermediate micro + macro, textbook order | D11: MA-05 | E11: Intermediate Macroeconomics | F11: Garín, Lester & Sims, Intermediate Macroeconomics (free PDF) Ch.5-6 Solow extensions | G11: Solow part 2: population, technology and the golden rule | H11: Explainer | I11: 12-15 min | J11: MA-04 | K11: University | L11: High | M11: Stale (median outlier age 8y+) | N11: 14 | O11: 4 | P11: 9 | Q11: 1 | R11: 15.73 | S11: 2.62 | T11: 13 | U11: Solow Growth Model | Part 4 | The Golden Rule | Intermediate Macroeconomics | V11: Tactical Economics | W11: 3370 | X11: 53000 | Y11: =IF(OR(W11="",W11=0,X11=""),"",X11/W11) -> 15.727003 | Z11: 6 | AA11: https://youtu.be/s5PFwvwNKiY | AB11: Planned | AE11: =IF(AB11<>"Published",COUNTIF($AB$2:AB11,"<>Published"),"") -> 10
A12: 11 | B12: =ROUNDUP(A12/3,0) -> 4 | C12: Phase 1: intermediate micro + macro, textbook order | D12: MI-06 | E12: Intermediate Microeconomics | F12: McAfee & Lewis, Introduction to Economic Analysis (CC BY-NC-SA) §12 Consumer Theory: utility | G12: Indifference curves and the budget constraint, visualised | H12: Explainer | I12: 10-12 min | J12: MI-01 | K12: University | L12: High | M12: Stale (median outlier age 8y+) | N12: 107 | O12: 29 | P12: 24 | Q12: 5 | R12: 6.53 | S12: 1.76 | T12: 8 | U12: indifference curves | V12: pajholden | W12: 47500 | X12: 255000 | Y12: =IF(OR(W12="",W12=0,X12=""),"",X12/W12) -> 5.3684211 | Z12: 17 | AA12: https://youtu.be/P_N2hr9aMow | AB12: Planned | AE12: =IF(AB12<>"Published",COUNTIF($AB$2:AB12,"<>Published"),"") -> 11
A13: 12 | B13: =ROUNDUP(A13/3,0) -> 4 | C13: Phase 1: intermediate micro + macro, textbook order | D13: MA-06 | E13: Intermediate Macroeconomics | F13: Garín, Lester & Sims, Intermediate Macroeconomics (free PDF) Ch.7 Growth accounting | G13: Growth accounting: how much of growth is capital, labour and ideas? | H13: Explainer | I13: 8-10 min | J13: MA-05 | K13: University | L13: Low | M13: - | N13: 1 | O13: 1 | P13: 0 | Q13: 0 | R13: 0.53 | S13: 0.18 | U13: Growth Accounting | V13: Klaus Prettner | W13: 8790 | X13: 4700 | Y13: =IF(OR(W13="",W13=0,X13=""),"",X13/W13) -> 0.53469852 | Z13: 3 | AA13: https://youtu.be/GDdM_MWh6xY | AB13: Planned | AE13: =IF(AB13<>"Published",COUNTIF($AB$2:AB13,"<>Published"),"") -> 12
A14: 13 | B14: =ROUNDUP(A14/3,0) -> 5 | C14: Phase 1: intermediate micro + macro, textbook order | D14: MI-07 | E14: Intermediate Microeconomics | F14: McAfee & Lewis, Introduction to Economic Analysis (CC BY-NC-SA) §12.3 Income & substitution effects | G14: Income vs substitution effects (the Slutsky decomposition, step by step) | H14: Explainer | I14: 10-12 min | J14: MI-06 | K14: University | L14: Medium | M14: Stale (median outlier age 8y+) | N14: 44 | O14: 16 | P14: 10 | Q14: 1 | R14: 5.11 | S14: 1.31 | T14: 11.5 | U14: Giffen Good Example - Price Change, Income and Substitution Effect - Intro to Microeconomics | V14: economicurtis | W14: 36200 | X14: 168000 | Y14: =IF(OR(W14="",W14=0,X14=""),"",X14/W14) -> 4.640884 | Z14: 14 | AA14: https://youtu.be/VRC-DVqKYCE | AB14: Planned | AE14: =IF(AB14<>"Published",COUNTIF($AB$2:AB14,"<>Published"),"") -> 13
A15: 14 | B15: =ROUNDUP(A15/3,0) -> 5 | C15: Phase 1: intermediate micro + macro, textbook order | D15: MA-07 | E15: Intermediate Macroeconomics | F15: Garín, Lester & Sims, Intermediate Macroeconomics (free PDF) Ch.9 Consumption | G15: Consumption smoothing: the two-period model and permanent income | H15: Explainer | I15: 10-12 min | J15: MI-06 | K15: University | L15: Low | M15: - | N15: 8 | O15: 3 | P15: 0 | Q15: 0 | R15: 0.65 | S15: 0.17 | U15: Two Period Utility Maximization: Introduction to Inter-temporal | V15: BurkeyAcademy | W15: 37100 | X15: 24000 | Y15: =IF(OR(W15="",W15=0,X15=""),"",X15/W15) -> 0.64690027 | Z15: 9 | AA15: https://youtu.be/0bQh3J82edU | AB15: Planned | AE15: =IF(AB15<>"Published",COUNTIF($AB$2:AB15,"<>Published"),"") -> 14
A16: 15 | B16: =ROUNDUP(A16/3,0) -> 5 | C16: Phase 1: intermediate micro + macro, textbook order | D16: MI-29 | E16: Intermediate Microeconomics | F16: McAfee & Lewis, Introduction to Economic Analysis (CC BY-NC-SA) §12.4 Labour supply | G16: The labour-leisure choice: why higher wages don't always mean more work | H16: Explainer | I16: 8-10 min | J16: MI-07 | K16: University | L16: Medium | M16: Stale (median outlier age 8y+) | N16: 7 | O16: 3 | P16: 1 | Q16: 0 | R16: 2.13 | S16: 0.13 | T16: 17 | U16: substitution and income effects on the backward bending supply curve of labour | V16: pajholden | W16: 47500 | X16: 101000 | Y16: =IF(OR(W16="",W16=0,X16=""),"",X16/W16) -> 2.1263158 | Z16: 17 | AA16: https://youtu.be/R-VCNJKsvwg | AB16: Planned | AE16: =IF(AB16<>"Published",COUNTIF($AB$2:AB16,"<>Published"),"") -> 15
A17: 16 | B17: =ROUNDUP(A17/3,0) -> 6 | C17: Phase 1: intermediate micro + macro, textbook order | D17: MA-26 | E17: Intermediate Macroeconomics | F17: Garín, Lester & Sims, Intermediate Macroeconomics (free PDF) Ch.8 Investment | G17: Investment: Tobin's q and the user cost of capital | H17: Explainer | I17: 8-10 min | J17: MA-03 | K17: University | L17: Low | M17: - | N17: 6 | O17: 5 | P17: 0 | Q17: 0 | R17: 0.27 | S17: 0.07 | U17: Change In Investment Demand and the Loanable Funds Market - Intermediate Macroeconomics | V17: economicurtis | W17: 36200 | X17: 9300 | Y17: =IF(OR(W17="",W17=0,X17=""),"",X17/W17) -> 0.25690608 | Z17: 14 | AA17: https://youtu.be/2j780pByEeI | AB17: Planned | AE17: =IF(AB17<>"Published",COUNTIF($AB$2:AB17,"<>Published"),"") -> 16
A18: 17 | B18: =ROUNDUP(A18/3,0) -> 6 | C18: Phase 1: intermediate micro + macro, textbook order | D18: MI-30 | E18: Intermediate Microeconomics | F18: McAfee & Lewis, Introduction to Economic Analysis (CC BY-NC-SA) §12.5 Intertemporal choice | G18: Saving and borrowing: the intertemporal budget constraint | H18: Explainer | I18: 8-10 min | J18: MI-06 | K18: University | L18: Low | M18: - | N18: 4 | O18: 3 | P18: 0 | Q18: 0 | R18: 0.34 | S18: 0.17 | U18: Intertemporal Utility Maximization: Two Period Example Problems | V18: BurkeyAcademy | W18: 37100 | X18: 9700 | Y18: =IF(OR(W18="",W18=0,X18=""),"",X18/W18) -> 0.26145553 | Z18: 9 | AA18: https://youtu.be/jEdU6wizLF0 | AB18: Planned | AE18: =IF(AB18<>"Published",COUNTIF($AB$2:AB18,"<>Published"),"") -> 17
A19: 18 | B19: =ROUNDUP(A19/3,0) -> 6 | C19: Phase 1: intermediate micro + macro, textbook order | D19: MA-08 | E19: Intermediate Macroeconomics | F19: Garín, Lester & Sims, Intermediate Macroeconomics (free PDF) Ch.12 Labour market | G19: Unemployment: natural rate, cyclical and the labour market diagram | H19: Explainer | I19: 8-10 min | J19: MA-01 | K19: IB/A-level/AP | L19: Medium | M19: Ageing (4-8y) | N19: 26 | O19: 18 | P19: 1 | Q19: 0 | R19: 1.11 | S19: 1.77 | T19: 6 | U19: How to Calculate the Unemployment Rate | Macroeconomics | Think Econ | V19: Think Econ | W19: 77800 | X19: 46000 | Y19: =IF(OR(W19="",W19=0,X19=""),"",X19/W19) -> 0.59125964 | Z19: 3 | AA19: https://youtu.be/3FudpA_fCGQ | AB19: Planned | AE19: =IF(AB19<>"Published",COUNTIF($AB$2:AB19,"<>Published"),"") -> 18
A20: 19 | B20: =ROUNDUP(A20/3,0) -> 7 | C20: Phase 1: intermediate micro + macro, textbook order | D20: MI-08 | E20: Intermediate Microeconomics | F20: McAfee & Lewis, Introduction to Economic Analysis (CC BY-NC-SA) §12.1 Marginal utility | G20: Marginal utility and why demand slopes down | H20: Explainer | I20: 6-8 min | J20: MI-06 | K20: IB/A-level | L20: High | M20: Stale (median outlier age 8y+) | N20: 27 | O20: 17 | P20: 7 | Q20: 1 | R20: 14.64 | S20: 1.83 | T20: 12 | U20: Utility & Marginal Utility | V20: Principles of Microeconomics | W20: 11200 | X20: 164000 | Y20: =IF(OR(W20="",W20=0,X20=""),"",X20/W20) -> 14.642857 | Z20: 8 | AA20: https://youtu.be/DRLS86XfHLg | AB20: Planned | AE20: =IF(AB20<>"Published",COUNTIF($AB$2:AB20,"<>Published"),"") -> 19
A21: 20 | B21: =ROUNDUP(A21/3,0) -> 7 | C21: Phase 1: intermediate micro + macro, textbook order | D21: MA-09 | E21: Intermediate Macroeconomics | F21: Garín, Lester & Sims, Intermediate Macroeconomics (free PDF) Ch.15 Money | G21: How banks create money (the balance-sheet version) | H21: Explainer | I21: 8-10 min | J21: None | K21: IB/A-level/AP | L21: Medium | M21: Stale (median outlier age 8y+) | N21: 34 | O21: 23 | P21: 3 | Q21: 0 | R21: 2.18 | S21: 0.45 | T21: 8 | U21: 💲 Money Creation | How does it work? | V21: EconClips | W21: 113000 | X21: 246000 | Y21: =IF(OR(W21="",W21=0,X21=""),"",X21/W21) -> 2.1769912 | Z21: 8 | AA21: https://youtu.be/3zAvyTKj5-0 | AB21: Planned | AE21: =IF(AB21<>"Published",COUNTIF($AB$2:AB21,"<>Published"),"") -> 20
A22: 21 | B22: =ROUNDUP(A22/3,0) -> 7 | C22: Phase 1: intermediate micro + macro, textbook order | D22: MI-09 | E22: Intermediate Microeconomics | F22: McAfee & Lewis, Introduction to Economic Analysis (CC BY-NC-SA) §9 Producer Theory: cost curves | G22: How to calculate marginal, average and total cost (and draw the curves) | H22: Worked problem ("how to solve") | I22: 8-10 min | J22: None | K22: IB/A-level/AP | L22: Medium | M22: Stale (median outlier age 8y+) | N22: 62 | O22: 24 | P22: 11 | Q22: 1 | R22: 10.22 | S22: 1.42 | T22: 14 | U22: How to Calculate Marginal Cost, Average Total Cost, Average Variable Cost, and Average Fixed Cost | V22: economicurtis | W22: 36200 | X22: 370000 | Y22: =IF(OR(W22="",W22=0,X22=""),"",X22/W22) -> 10.220994 | Z22: 14 | AA22: https://youtu.be/3-j-rZ6hz74 | AB22: Planned | AE22: =IF(AB22<>"Published",COUNTIF($AB$2:AB22,"<>Published"),"") -> 21
A23: 22 | B23: =ROUNDUP(A23/3,0) -> 8 | C23: Phase 1: intermediate micro + macro, textbook order | D23: MA-10 | E23: Intermediate Macroeconomics | F23: Garín, Lester & Sims, Intermediate Macroeconomics (free PDF) Ch.16 The IS curve | G23: The IS curve, derived: goods-market equilibrium and the multiplier | H23: Explainer | I23: 10-12 min | J23: MA-07 | K23: University | L23: Medium | M23: Stale (median outlier age 8y+) | N23: 18 | O23: 15 | P23: 4 | Q23: 1 | R23: 8.37 | S23: 1.37 | T23: 8.5 | U23: Macro Problem - Calculate the IS Curve & LM Curve Equations - Equilibrium Interest Rate & Output | V23: economicurtis | W23: 36200 | X23: 303000 | Y23: =IF(OR(W23="",W23=0,X23=""),"",X23/W23) -> 8.3701657 | Z23: 13 | AA23: https://youtu.be/pAX7mR4ii5Y | AB23: Planned | AE23: =IF(AB23<>"Published",COUNTIF($AB$2:AB23,"<>Published"),"") -> 22
A24: 23 | B24: =ROUNDUP(A24/3,0) -> 8 | C24: Phase 1: intermediate micro + macro, textbook order | D24: MI-10 | E24: Intermediate Microeconomics | F24: McAfee & Lewis, Introduction to Economic Analysis (CC BY-NC-SA) §9.3 Returns to scale | G24: Economies of scale and the long-run average cost curve | H24: Explainer | I24: 6-8 min | J24: MI-09 | K24: IB/A-level/AP | L24: High | M24: Stale (median outlier age 8y+) | N24: 45 | O24: 22 | P24: 6 | Q24: 0 | R24: 6.11 | S24: 3.05 | T24: 13 | U24: Long run average total cost curve relating to economies and diseconomies of scale | V24: Free Econ Help | W24: 38300 | X24: 234000 | Y24: =IF(OR(W24="",W24=0,X24=""),"",X24/W24) -> 6.1096606 | Z24: 14 | AA24: https://youtu.be/URIjtaP6SPk | AB24: Planned | AE24: =IF(AB24<>"Published",COUNTIF($AB$2:AB24,"<>Published"),"") -> 23
A25: 24 | B25: =ROUNDUP(A25/3,0) -> 8 | C25: Phase 1: intermediate micro + macro, textbook order | D25: MA-11 | E25: Intermediate Macroeconomics | F25: Garín, Lester & Sims, Intermediate Macroeconomics (free PDF) Ch.17 The LM curve | G25: The LM curve, derived: money-market equilibrium | H25: Explainer | I25: 8-10 min | J25: MA-10 | K25: University | L25: Medium | M25: Stale (median outlier age 8y+) | N25: 5 | O25: 4 | P25: 3 | Q25: 0 | R25: 8.37 | S25: 0.64 | T25: 13 | U25: Macro Problem - Calculate the IS Curve & LM Curve Equations - Equilibrium Interest Rate & Output | V25: economicurtis | W25: 36200 | X25: 303000 | Y25: =IF(OR(W25="",W25=0,X25=""),"",X25/W25) -> 8.3701657 | Z25: 13 | AA25: https://youtu.be/pAX7mR4ii5Y | AB25: Planned | AE25: =IF(AB25<>"Published",COUNTIF($AB$2:AB25,"<>Published"),"") -> 24
A26: 25 | B26: =ROUNDUP(A26/3,0) -> 9 | C26: Phase 2: micro / macro / game theory / econometrics rotation; micro & macro anchors | D26: MI-11 | E26: Intermediate Microeconomics | F26: McAfee & Lewis, Introduction to Economic Analysis (CC BY-NC-SA) §9.1 Production functions | G26: Cobb-Douglas: the production function that runs economics | H26: Explainer | I26: 8-10 min | J26: MI-09 | K26: University | L26: High | M26: Stale (median outlier age 8y+) | N26: 98 | O26: 21 | P26: 12 | Q26: 0 | R26: 9.7 | S26: 4.63 | T26: 12 | U26: Cobb-Douglas Production Function Differentiation Example | V26: economicurtis | W26: 36200 | X26: 351000 | Y26: =IF(OR(W26="",W26=0,X26=""),"",X26/W26) -> 9.6961326 | Z26: 14 | AA26: https://youtu.be/rYsNHYgIUL4 | AB26: Planned | AE26: =IF(AB26<>"Published",COUNTIF($AB$2:AB26,"<>Published"),"") -> 25
A27: 26 | B27: =ROUNDUP(A27/3,0) -> 9 | C27: Phase 2: micro / macro / game theory / econometrics rotation; micro & macro anchors | D27: MA-12 | E27: Intermediate Macroeconomics | F27: Garín, Lester & Sims, Intermediate Macroeconomics (free PDF) Ch.18 IS-LM | G27: The IS-LM model: fiscal and monetary policy in one diagram | H27: Explainer | I27: 12-15 min | J27: MA-11, MA-12 | K27: University | L27: High | M27: Ageing (4-8y) | N27: 29 | O27: 11 | P27: 12 | Q27: 2 | R27: 5.93 | S27: 1.25 | T27: 4.5 | U27: Introduction to IS LM model | V27: Free Econ Help | W27: 38300 | X27: 227000 | Y27: =IF(OR(W27="",W27=0,X27=""),"",X27/W27) -> 5.926893 | Z27: 14 | AA27: https://youtu.be/Q3hoC8lDCBo | AB27: Planned | AE27: =IF(AB27<>"Published",COUNTIF($AB$2:AB27,"<>Published"),"") -> 26
A28: 27 | B28: =ROUNDUP(A28/3,0) -> 9 | C28: Phase 2: micro / macro / game theory / econometrics rotation; micro & macro anchors | D28: GT-01 | E28: Game Theory | F28: Bonanno, Game Theory (open access, UC Davis) Ch.1 Strategic games | G28: Game theory from zero: payoff matrices and dominant strategies | H28: Explainer | I28: 8-10 min | J28: None | K28: IB/University | L28: High | M28: Stale (median outlier age 8y+) | N28: 13 | O28: 11 | P28: 7 | Q28: 2 | R28: 25.65 | S28: 2.36 | T28: 8 | U28: Intro to Game Theory and the Dominant Strategy Equilibrium | V28: The Economics Detective | W28: 34000 | X28: 872000 | Y28: =IF(OR(W28="",W28=0,X28=""),"",X28/W28) -> 25.647059 | Z28: 13 | AA28: https://youtu.be/3Y1WpytiHKE | AB28: Planned | AE28: =IF(AB28<>"Published",COUNTIF($AB$2:AB28,"<>Published"),"") -> 27
A29: 28 | B29: =ROUNDUP(A29/3,0) -> 10 | C29: Phase 2: micro / macro / game theory / econometrics rotation; micro & macro anchors | D29: EC-01 | E29: Econometrics | F29: Hanck et al., Introduction to Econometrics with R (CC BY-NC-SA) Ch.4 Simple regression | G29: Simple linear regression: what OLS actually minimises (and why) | H29: Explainer | I29: 10-12 min | J29: PS-27 (stats lane) | K29: University | L29: High | M29: Stale (median outlier age 8y+) | N29: 24 | O29: 8 | P29: 5 | Q29: 3 | R29: 13.67 | S29: 1.72 | T29: 12 | U29: Econometrics // Lecture 3: OLS and Goodness-Of-Fit (R-Squared) | V29: KeynesAcademy | W29: 28100 | X29: 384000 | Y29: =IF(OR(W29="",W29=0,X29=""),"",X29/W29) -> 13.66548 | Z29: 13 | AA29: https://youtu.be/8tAPsX0YuNE | AB29: Planned | AE29: =IF(AB29<>"Published",COUNTIF($AB$2:AB29,"<>Published"),"") -> 28
A30: 29 | B30: =ROUNDUP(A30/3,0) -> 10 | C30: Phase 2: micro / macro / game theory / econometrics rotation; micro & macro anchors | D30: MI-28 | E30: Intermediate Microeconomics | F30: McAfee & Lewis, Introduction to Economic Analysis (CC BY-NC-SA) (whole) | G30: ALL of Intermediate Microeconomics in 20 minutes | H30: Anchor (ALL of…) | I30: 20 min | J30: MI-01…MI-27 | K30: University | L30: High | M30: Fresh (<4y) | N30: 11 | O30: 5 | P30: 9 | Q30: 8 | R30: 36.21 | S30: 36.21 | T30: 3 | U30: The Entire Economics Degree in 20 Minutes | V30: 20 Minute University | W30: 145000 | X30: 3100000 | Y30: =IF(OR(W30="",W30=0,X30=""),"",X30/W30) -> 21.37931 | Z30: 1 | AA30: https://youtu.be/NngM_qdDMm8 | AB30: Planned | AE30: =IF(AB30<>"Published",COUNTIF($AB$2:AB30,"<>Published"),"") -> 29
... A46: 45 | B46: =ROUNDUP(A46/3,0) -> 15 | C46: Phase 2: micro / macro / game theory / econometrics rotation; micro & macro anchors | D46: GT-05 | E46: Game Theory | F46: Bonanno, Game Theory (open access, UC Davis) Ch.4 Subgame perfection | G46: Subgame perfect equilibrium: the threats that aren't credible | H46: Explainer | I46: 10-12 min | J46: GT-04 | K46: University | L46: Medium | M46: Stale (median outlier age 8y+) | N46: 2 | O46: 2 | P46: 1 | Q46: 0 | R46: 5.21 | S46: 0.4 | T46: 13 | U46: Subgame Perfect Nash Equilibrium | V46: The Economics Detective | W46: 34000 | X46: 177000 | Y46: =IF(OR(W46="",W46=0,X46=""),"",X46/W46) -> 5.2058824 | Z46: 13 | AA46: https://youtu.be/dTTFzBlpdKA | AB46: Planned | AE46: =IF(AB46<>"Published",COUNTIF($AB$2:AB46,"<>Published"),"") -> 45
A47: 46 | B47: =ROUNDUP(A47/3,0) -> 16 | C47: Phase 2: micro / macro / game theory / econometrics rotation; micro & macro anchors | D47: EC-05 | E47: Econometrics | F47: Hanck et al., Introduction to Econometrics with R (CC BY-NC-SA) Ch.6.4 Multicollinearity | G47: Multicollinearity: why your coefficients went crazy | H47: Explainer | I47: 8-10 min | J47: EC-04 | K47: University | L47: Low | M47: - | N47: 2 | O47: 1 | P47: 0 | Q47: 0 | R47: 0.11 | S47: 0.11 | U47: Multicollinearity – Meaning, Types, Causes, Detection (Econometrics) | V47: Mini Sethi | W47: 92800 | X47: 10000 | Y47: =IF(OR(W47="",W47=0,X47=""),"",X47/W47) -> 0.10775862 | Z47: 1 | AA47: https://youtu.be/VQEPk_SIYT0 | AB47: Planned | AE47: =IF(AB47<>"Published",COUNTIF($AB$2:AB47,"<>Published"),"") -> 46
A48: 47 | B48: =ROUNDUP(A48/3,0) -> 16 | C48: Phase 2: micro / macro / game theory / econometrics rotation; micro & macro anchors | D48: MI-16 | E48: Intermediate Microeconomics | F48: McAfee & Lewis, Introduction to Economic Analysis (CC BY-NC-SA) §15.4 Price discrimination | G48: Price discrimination: why the same seat costs three prices | H48: Explainer | I48: 8-10 min | J48: MI-14 | K48: IB/A-level | L48: Medium | M48: Stale (median outlier age 8y+) | N48: 42 | O48: 18 | P48: 4 | Q48: 0 | R48: 7.35 | S48: 0.61 | T48: 13 | U48: Price discrimination | V48: Economics Online | W48: 5990 | X48: 44000 | Y48: =IF(OR(W48="",W48=0,X48=""),"",X48/W48) -> 7.345576 | Z48: 12 | AA48: https://youtu.be/IZ1iAYhQnwg | AB48: Planned | AE48: =IF(AB48<>"Published",COUNTIF($AB$2:AB48,"<>Published"),"") -> 47
A49: 48 | B49: =ROUNDUP(A49/3,0) -> 16 | C49: Phase 2: micro / macro / game theory / econometrics rotation; micro & macro anchors | D49: MA-17 | E49: Intermediate Macroeconomics | F49: Garín, Lester & Sims, Intermediate Macroeconomics (free PDF) Ch.24 Open economy | G49: Exchange rates and the balance of payments, explained | H49: Explainer | I49: 10-12 min | J49: MA-01 | K49: IB/A-level | L49: Medium | M49: Stale (median outlier age 8y+) | N49: 116 | O49: 28 | P49: 11 | Q49: 0 | R49: 3.03 | S49: 0.84 | T49: 8 | U49: balance of payments - structure of the current account | V49: pajholden | W49: 47500 | X49: 144000 | Y49: =IF(OR(W49="",W49=0,X49=""),"",X49/W49) -> 3.0315789 | Z49: 18 | AA49: https://youtu.be/JKRBpJZ92QM | AB49: Planned | AE49: =IF(AB49<>"Published",COUNTIF($AB$2:AB49,"<>Published"),"") -> 48
A50: 49 | B50: =ROUNDUP(A50/3,0) -> 17 | C50: Phase 3: econometrics & game theory heavy; IB anchor; remaining topics | D50: GT-06 | E50: Game Theory | F50: Bonanno, Game Theory (open access, UC Davis) Ch.5 Mixed strategies | G50: Mixed strategies: how to solve for the probabilities | H50: Worked problem ("how to solve") | I50: 10-12 min | J50: GT-02 | K50: University | L50: Medium | M50: Stale (median outlier age 8y+) | N50: 15 | O50: 4 | P50: 6 | Q50: 0 | R50: 3.62 | S50: 0.9 | T50: 13 | U50: Mixed Strategies Nash Equilibrium: The Math | V50: Ashley Hodgson | W50: 55600 | X50: 201000 | Y50: =IF(OR(W50="",W50=0,X50=""),"",X50/W50) -> 3.6151079 | Z50: 4 | AA50: https://youtu.be/S49oKtISkqI | AB50: Planned | AE50: =IF(AB50<>"Published",COUNTIF($AB$2:AB50,"<>Published"),"") -> 49
A51: 50 | B51: =ROUNDUP(A51/3,0) -> 17 | C51: Phase 3: econometrics & game theory heavy; IB anchor; remaining topics | D51: EC-06 | E51: Econometrics | F51: Hanck et al., Introduction to Econometrics with R (CC BY-NC-SA) Ch.5.4 Heteroskedasticity | G51: Heteroskedasticity and robust standard errors | H51: Explainer | I51: 8-10 min | J51: EC-03 | K51: University | L51: Medium | M51: Ageing (4-8y) | N51: 3 | O51: 3 | P51: 1 | Q51: 0 | R51: 2.54 | S51: 0.51 | T51: 5 | U51: Wooldridge Econometrics for Economics BSc students Ch. 8: Heteroskedasticity | V51: youtube-economist | W51: 7880 | X51: 20000 | Y51: =IF(OR(W51="",W51=0,X51=""),"",X51/W51) -> 2.5380711 | Z51: 5 | AA51: https://youtu.be/DMzBRYqAHrE | AB51: Planned | AE51: =IF(AB51<>"Published",COUNTIF($AB$2:AB51,"<>Published"),"") -> 50
A52: 51 | B52: =ROUNDUP(A52/3,0) -> 17 | C52: Phase 3: econometrics & game theory heavy; IB anchor; remaining topics | D52: EC-07 | E52: Econometrics | F52: Hanck et al., Introduction to Econometrics with R (CC BY-NC-SA) Ch.8 Nonlinear | G52: Logs in regression: how to read elasticities and percent changes | H52: Explainer | I52: 8-10 min | J52: EC-04 | K52: University | L52: Medium | M52: Stale (median outlier age 8y+) | N52: 11 | O52: 4 | P52: 4 | Q52: 0 | R52: 4.2 | S52: 0.32 | T52: 13 | U52: Log-Log Regression & Interpretation (What do the Regression Coefficient Estimate Results Mean?) | V52: economicurtis | W52: 36200 | X52: 152000 | Y52: =IF(OR(W52="",W52=0,X52=""),"",X52/W52) -> 4.198895 | Z52: 13 | AA52: https://youtu.be/NZCSt9WkpkI | AB52: Planned | AE52: =IF(AB52<>"Published",COUNTIF($AB$2:AB52,"<>Published"),"") -> 51
A53: 52 | B53: =ROUNDUP(A53/3,0) -> 18 | C53: Phase 3: econometrics & game theory heavy; IB anchor; remaining topics | D53: GT-07 | E53: Game Theory | F53: Bonanno, Game Theory (open access, UC Davis) Ch.7 Repeated games | G53: Repeated games and tit-for-tat: how cooperation survives | H53: Explainer | I53: 10-12 min | J53: GT-03 | K53: University | L53: Low | M53: - | N53: 4 | O53: 4 | P53: 0 | Q53: 0 | R53: 0.86 | S53: 0.22 | U53: Repeated Games in Game Theory | V53: Ashley Hodgson | W53: 55600 | X53: 48000 | Y53: =IF(OR(W53="",W53=0,X53=""),"",X53/W53) -> 0.86330935 | Z53: 4 | AA53: https://youtu.be/A0sR5pz69IE | AB53: Planned | AE53: =IF(AB53<>"Published",COUNTIF($AB$2:AB53,"<>Published"),"") -> 52
A54: 53 | B54: =ROUNDUP(A54/3,0) -> 18 | C54: Phase 3: econometrics & game theory heavy; IB anchor; remaining topics | D54: MI-17 | E54: Intermediate Microeconomics | F54: McAfee & Lewis, Introduction to Economic Analysis (CC BY-NC-SA) §17 Oligopoly: Cournot | G54: How to solve a Cournot oligopoly problem | H54: Worked problem ("how to solve") | I54: 10-12 min | J54: MI-14, GT-01 | K54: University | L54: Medium | M54: Stale (median outlier age 8y+) | N54: 16 | O54: 9 | P54: 4 | Q54: 1 | R54: 8.25 | S54: 1.43 | T54: 11 | U54: How to Solve a Cournot Oligopoly Problem | V54: Economics in Many Lessons | W54: 82800 | X54: 683000 | Y54: =IF(OR(W54="",W54=0,X54=""),"",X54/W54) -> 8.2487923 | Z54: 13 | AA54: https://youtu.be/An_2r6Ae_28 | AB54: Planned | AE54: =IF(AB54<>"Published",COUNTIF($AB$2:AB54,"<>Published"),"") -> 53
A55: 54 | B55: =ROUNDUP(A55/3,0) -> 18 | C55: Phase 3: econometrics & game theory heavy; IB anchor; remaining topics | D55: MA-18 | E55: Intermediate Macroeconomics | F55: Garín, Lester & Sims, Intermediate Macroeconomics (free PDF) Ch.25 Mundell-Fleming | G55: The Mundell-Fleming model: the trilemma every central bank faces | H55: Explainer | I55: 12-15 min | J55: MA-13, MA-18 | K55: University | L55: Medium | M55: Fresh (<4y) | N55: 7 | O55: 6 | P55: 2 | Q55: 1 | R55: 3.07 | S55: 1.54 | T55: 3.5 | U55: The Mundell-Fleming Model by Vidhi Kalra | V55: 5 Minute Economics | W55: 99200 | X55: 167000 | Y55: =IF(OR(W55="",W55=0,X55=""),"",X55/W55) -> 1.6834677 | Z55: 5 | AA55: https://youtu.be/U7K2OTQj4ZQ | AB55: Planned | AE55: =IF(AB55<>"Published",COUNTIF($AB$2:AB55,"<>Published"),"") -> 54
...

Sheet Schedule
A1: Week | B1: Phase | C1: Video 1 | D1: Video 2 | E1: Video 3
A2: 1 | B2: Phase 1: intermediate micro + macro, textbook order | C2: MI-01 Supply and demand, properly: what shifts a curve and what moves along it | D2: MA-01 GDP, properly: three ways to measure one number | E2: MI-02 How to solve elasticity problems (point, arc, revenue test)
A3: 2 | B3: Phase 1: intermediate micro + macro, textbook order | C3: MA-02 Inflation, the CPI and the GDP deflator (and why they disagree) | D3: MI-03 How to calculate opportunity cost (and why the PPF is curved) | E3: MA-03 The aggregate production function and diminishing returns to capital
A4: 3 | B4: Phase 1: intermediate micro + macro, textbook order | C4: MI-04 Consumer and producer surplus: how to calculate them from a graph | D4: MA-04 The Solow growth model, part 1: the diagram and the steady state | E4: MI-05 Price ceilings, floors and taxes: who really pays?
A5: 4 | B5: Phase 1: intermediate micro + macro, textbook order | C5: MA-05 Solow part 2: population, technology and the golden rule | D5: MI-06 Indifference curves and the budget constraint, visualised | E5: MA-06 Growth accounting: how much of growth is capital, labour and ideas?
A6: 5 | B6: Phase 1: intermediate micro + macro, textbook order | C6: MI-07 Income vs substitution effects (the Slutsky decomposition, step by step) | D6: MA-07 Consumption smoothing: the two-period model and permanent income | E6: MI-29 The labour-leisure choice: why higher wages don't always mean more work
A7: 6 | B7: Phase 1: intermediate micro + macro, textbook order | C7: MA-26 Investment: Tobin's q and the user cost of capital | D7: MI-30 Saving and borrowing: the intertemporal budget constraint | E7: MA-08 Unemployment: natural rate, cyclical and the labour market diagram
A8: 7 | B8: Phase 1: intermediate micro + macro, textbook order | C8: MI-08 Marginal utility and why demand slopes down | D8: MA-09 How banks create money (the balance-sheet version) | E8: MI-09 How to calculate marginal, average and total cost (and draw the curves)
A9: 8 | B9: Phase 1: intermediate micro + macro, textbook order | C9: MA-10 The IS curve, derived: goods-market equilibrium and the multiplier | D9: MI-10 Economies of scale and the long-run average cost curve | E9: MA-11 The LM curve, derived: money-market equilibrium
A10: 9 | B10: Phase 2: micro / macro / game theory / econometrics rotation; micro & macro anchors | C10: MI-11 Cobb-Douglas: the production function that runs economics | D10: MA-12 The IS-LM model: fiscal and monetary policy in one diagram | E10: GT-01 Game theory from zero: payoff matrices and dominant strategies
A11: 10 | B11: Phase 2: micro / macro / game theory / econometrics rotation; micro & macro anchors | C11: EC-01 Simple linear regression: what OLS actually minimises (and why) | D11: MI-28 ALL of Intermediate Microeconomics in 20 minutes | E11: MI-12 Perfect competition: profit maximisation and the shutdown rule
A12: 11 | B12: Phase 2: micro / macro / game theory / econometrics rotation; micro & macro anchors | C12: MA-13 The AD-AS model: demand and supply shocks, short run to long run | D12: GT-02 How to find a Nash equilibrium in a 2×2 game | E12: EC-02 R² explained: what it measures and the three ways people misuse it
A13: 12 | B13: Phase 2: micro / macro / game theory / econometrics rotation; micro & macro anchors | C13: MI-13 From short run to long run in perfect competition (why profits vanish) | D13: MA-14 The Phillips curve: why it worked, broke, and came back | E13: GT-03 The prisoner's dilemma: why rational players lose
... A34: 33 | B34: Phase 4: compressions & format experiments | C34: XC-02 Supply and demand in 5 levels: high school to PhD | D34: XC-03 How Solow discovered that capital isn't what makes countries rich | E34: EC-25 ALL of Econometrics in 20 minutes
A35: 34 | B35: Phase 4: compressions & format experiments | C35: XC-01 The Entire Economics Degree, explained properly, in 30 minutes

Sheet By Course
A1: Course | B1: Code | C1: Working title | D1: Source section | E1: Format | F1: Length | G1: Prerequisites | H1: Exam tag | I1: Demand signal | J1: Supply age | K1: Production order
A2: Intermediate Microeconomics | B2: MI-01 | C2: Supply and demand, properly: what shifts a curve and what moves along it | D2: McAfee & Lewis, Introduction to Economic Analysis (CC BY-NC-SA) §2 Supply and Demand | E2: Explainer | F2: 8-10 min | G2: None | H2: IB/A-level/AP | I2: High | J2: Stale (median outlier age 8y+) | K2: 1
A3: Intermediate Microeconomics | B3: MI-02 | C3: How to solve elasticity problems (point, arc, revenue test) | D3: McAfee & Lewis, Introduction to Economic Analysis (CC BY-NC-SA) §2.3 Elasticity | E3: Worked problem ("how to solve") | F3: 8-10 min | G3: MI-01 | H3: IB/A-level/AP | I3: High | J3: Stale (median outlier age 8y+) | K3: 3
A4: Intermediate Microeconomics | B4: MI-03 | C4: How to calculate opportunity cost (and why the PPF is curved) | D4: McAfee & Lewis, Introduction to Economic Analysis (CC BY-NC-SA) §2.1 Opportunity cost / PPF | E4: Worked problem ("how to solve") | F4: 6-8 min | G4: None | H4: IB/A-level/AP | I4: High | J4: Stale (median outlier age 8y+) | K4: 5
A5: Intermediate Microeconomics | B5: MI-04 | C5: Consumer and producer surplus: how to calculate them from a graph | D5: McAfee & Lewis, Introduction to Economic Analysis (CC BY-NC-SA) §2.5 Surplus | E5: Worked problem ("how to solve") | F5: 6-8 min | G5: MI-01 | H5: IB/A-level/AP | I5: High | J5: Stale (median outlier age 8y+) | K5: 7
A6: Intermediate Microeconomics | B6: MI-05 | C6: Price ceilings, floors and taxes: who really pays? | D6: McAfee & Lewis, Introduction to Economic Analysis (CC BY-NC-SA) §5 Government interventions | E6: Explainer | F6: 8-10 min | G6: MI-04 | H6: IB/A-level | I6: Medium | J6: Stale (median outlier age 8y+) | K6: 9
A7: Intermediate Microeconomics | B7: MI-06 | C7: Indifference curves and the budget constraint, visualised | D7: McAfee & Lewis, Introduction to Economic Analysis (CC BY-NC-SA) §12 Consumer Theory: utility | E7: Explainer | F7: 10-12 min | G7: MI-01 | H7: University | I7: High | J7: Stale (median outlier age 8y+) | K7: 11
A8: Intermediate Microeconomics | B8: MI-07 | C8: Income vs substitution effects (the Slutsky decomposition, step by step) | D8: McAfee & Lewis, Introduction to Economic Analysis (CC BY-NC-SA) §12.3 Income & substitution effects | E8: Explainer | F8: 10-12 min | G8: MI-06 | H8: University | I8: Medium | J8: Stale (median outlier age 8y+) | K8: 13
A9: Intermediate Microeconomics | B9: MI-08 | C9: Marginal utility and why demand slopes down | D9: McAfee & Lewis, Introduction to Economic Analysis (CC BY-NC-SA) §12.1 Marginal utility | E9: Explainer | F9: 6-8 min | G9: MI-06 | H9: IB/A-level | I9: High | J9: Stale (median outlier age 8y+) | K9: 19
A10: Intermediate Microeconomics | B10: MI-09 | C10: How to calculate marginal, average and total cost (and draw the curves) | D10: McAfee & Lewis, Introduction to Economic Analysis (CC BY-NC-SA) §9 Producer Theory: cost curves | E10: Worked problem ("how to solve") | F10: 8-10 min | G10: None | H10: IB/A-level/AP | I10: Medium | J10: Stale (median outlier age 8y+) | K10: 21
A11: Intermediate Microeconomics | B11: MI-10 | C11: Economies of scale and the long-run average cost curve | D11: McAfee & Lewis, Introduction to Economic Analysis (CC BY-NC-SA) §9.3 Returns to scale | E11: Explainer | F11: 6-8 min | G11: MI-09 | H11: IB/A-level/AP | I11: High | J11: Stale (median outlier age 8y+) | K11: 23
A12: Intermediate Microeconomics | B12: MI-11 | C12: Cobb-Douglas: the production function that runs economics | D12: McAfee & Lewis, Introduction to Economic Analysis (CC BY-NC-SA) §9.1 Production functions | E12: Explainer | F12: 8-10 min | G12: MI-09 | H12: University | I12: High | J12: Stale (median outlier age 8y+) | K12: 25
A13: Intermediate Microeconomics | B13: MI-12 | C13: Perfect competition: profit maximisation and the shutdown rule | D13: McAfee & Lewis, Introduction to Economic Analysis (CC BY-NC-SA) §10 Perfect competition | E13: Explainer | F13: 10-12 min | G13: MI-09 | H13: IB/A-level/AP | I13: High | J13: Ageing (4-8y) | K13: 30
... A101: Cross-course | B101: XC-04 | C101: Every IB Economics diagram in 15 minutes | D101: Exam funnel | E101: Anchor (ALL of…) | F101: 15 min | G101: MI-01…MA-18 | H101: IB | I101: High | J101: Stale (median outlier age 8y+) | K101: 63

Sheet Progress
A1: Progress
A3: By status | D3: By course | E3: Videos | F3: Published | H3: By demand signal | I3: Videos | K3: By supply age | L3: Videos
A4: Planned | B4: =COUNTIF(Backlog!$AB$2:$AB$101,A4) -> 100 | D4: Intermediate Microeconomics | E4: =COUNTIF(Backlog!$E$2:$E$101,D4) -> 30 | F4: =COUNTIFS(Backlog!$E$2:$E$101,D4,Backlog!$AB$2:$AB$101,"Published") -> 0 | H4: High | I4: =COUNTIF(Backlog!$L$2:$L$101,H4) -> 36 | K4: Stale (median outlier age 8y+) | L4: =COUNTIF(Backlog!$M$2:$M$101,K4) -> 52
A5: Scripted | B5: =COUNTIF(Backlog!$AB$2:$AB$101,A5) -> 0 | D5: Intermediate Macroeconomics | E5: =COUNTIF(Backlog!$E$2:$E$101,D5) -> 26 | F5: =COUNTIFS(Backlog!$E$2:$E$101,D5,Backlog!$AB$2:$AB$101,"Published") -> 0 | H5: Medium | I5: =COUNTIF(Backlog!$L$2:$L$101,H5) -> 40 | K5: Ageing (4-8y) | L5: =COUNTIF(Backlog!$M$2:$M$101,K5) -> 17
A6: Audio done | B6: =COUNTIF(Backlog!$AB$2:$AB$101,A6) -> 0 | D6: Game Theory | E6: =COUNTIF(Backlog!$E$2:$E$101,D6) -> 14 | F6: =COUNTIFS(Backlog!$E$2:$E$101,D6,Backlog!$AB$2:$AB$101,"Published") -> 0 | H6: Low | I6: =COUNTIF(Backlog!$L$2:$L$101,H6) -> 20 | K6: Fresh (<4y) | L6: =COUNTIF(Backlog!$M$2:$M$101,K6) -> 7
A7: Rendered | B7: =COUNTIF(Backlog!$AB$2:$AB$101,A7) -> 0 | D7: Econometrics | E7: =COUNTIF(Backlog!$E$2:$E$101,D7) -> 26 | F7: =COUNTIFS(Backlog!$E$2:$E$101,D7,Backlog!$AB$2:$AB$101,"Published") -> 0 | H7: No comparable video | I7: =COUNTIF(Backlog!$L$2:$L$101,H7) -> 4 | K7: - | L7: =COUNTIF(Backlog!$M$2:$M$101,K7) -> 24
A8: Published | B8: =COUNTIF(Backlog!$AB$2:$AB$101,A8) -> 0 | D8: Cross-course | E8: =COUNTIF(Backlog!$E$2:$E$101,D8) -> 4 | F8: =COUNTIFS(Backlog!$E$2:$E$101,D8,Backlog!$AB$2:$AB$101,"Published") -> 0
A9: Total | B9: =SUM(B4:B8) -> 100
A12: Next up (first 5 not yet published)
A13: =IFERROR(INDEX(Backlog!$D$2:$D$101,MATCH(1,Backlog!$AE$2:$AE$101,0)),"") -> MI-01 | B13: =IFERROR(INDEX(Backlog!$G$2:$G$101,MATCH(1,Backlog!$AE$2:$AE$101,0)),"") -> Supply and demand, properly: what shifts a curve and what moves along it
A14: =IFERROR(INDEX(Backlog!$D$2:$D$101,MATCH(2,Backlog!$AE$2:$AE$101,0)),"") -> MA-01 | B14: =IFERROR(INDEX(Backlog!$G$2:$G$101,MATCH(2,Backlog!$AE$2:$AE$101,0)),"") -> GDP, properly: three ways to measure one number
A15: =IFERROR(INDEX(Backlog!$D$2:$D$101,MATCH(3,Backlog!$AE$2:$AE$101,0)),"") -> MI-02 | B15: =IFERROR(INDEX(Backlog!$G$2:$G$101,MATCH(3,Backlog!$AE$2:$AE$101,0)),"") -> How to solve elasticity problems (point, arc, revenue test)
A16: =IFERROR(INDEX(Backlog!$D$2:$D$101,MATCH(4,Backlog!$AE$2:$AE$101,0)),"") -> MA-02 | B16: =IFERROR(INDEX(Backlog!$G$2:$G$101,MATCH(4,Backlog!$AE$2:$AE$101,0)),"") -> Inflation, the CPI and the GDP deflator (and why they disagree)
A17: =IFERROR(INDEX(Backlog!$D$2:$D$101,MATCH(5,Backlog!$AE$2:$AE$101,0)),"") -> MI-03 | B17: =IFERROR(INDEX(Backlog!$G$2:$G$101,MATCH(5,Backlog!$AE$2:$AE$101,0)),"") -> How to calculate opportunity cost (and why the PPF is curved)
