Workbook

Sheet Read Me
A1: University physics, explained visually: production backlog (100 videos)
A2: Built 2026-10-23 from OpenStax University Physics (CC BY 4.0) and the physics channel scan (244 channels, 33,889 videos).
A4: Courses and sources
A5: ME = Mechanics (28): OpenStax University Physics Vol. 1, Ch. 2-13.
A6: WO = Fluids, Oscillations, Waves & Sound (12): Vol. 1, Ch. 14-17.
A7: TH = Thermodynamics (8): Vol. 2, Ch. 1-4.
A8: EM = Electricity & Magnetism (24): Vol. 2, Ch. 5-16.
A9: OP = Optics (8): Vol. 3, Ch. 1-4.
A10: MP = Modern Physics (10): Vol. 3, Ch. 5-10 (relativity, photons, quantum mechanics, atoms, nuclear).
A11: MM = Maths methods (6): OpenStax Calculus Vol. 3 (vectors, gradient, divergence/curl, line & surface integrals, Stokes/divergence theorems) and the differential equations of first-year physics.
A12: XC = cross-course (4): the mechanics and waves anchors and the two 2-hour "explained slowly" sleep compilations.
A13: All sources are CC BY 4.0, so definitions, formulas, derivations and figures can be adapted with attribution; narration is written fresh.
... A26: Status and Publish date (yellow) are yours to edit; the Progress tab counts them.

Sheet Backlog
A1: Order | B1: Week | C1: Phase | D1: Code | E1: Course | F1: Source section (textbook) | G1: Working title | H1: Format | I1: Target length | J1: Prerequisites | K1: Exam tag | L1: Demand signal | M1: Supply age | N1: Videos found in scan | O1: Channels covering | P1: Small-ch outliers (raw) | Q1: Small-ch outliers (age-adj) | R1: Best small-ch Views/Subs | S1: Best small-ch Views/yr/Subs | T1: Median outlier age (yrs) | U1: Best evidence: video | V1: Evidence channel | W1: Evidence subs | X1: Evidence views | Y1: Views / Subs | Z1: Evidence age (yrs) | AA1: Evidence URL | AB1: Status | AC1: Publish date | AD1: Notes | AF1: Pending rank (helper)
A2: 1 | B2: =ROUNDUP(A2/3,0) -> 1 | C2: Phase 1: mechanics + E&M alternate, textbook order (two playlists) | D2: ME-01 | E2: Mechanics | F2: OpenStax University Physics Vol. 1 (CC BY 4.0) Ch.2 Vectors | G2: Vectors: components, dot and cross product in one animation | H2: Explainer (one concept, one animation) | I2: 6-8 min | J2: None | K2: A-level/IB/AP | L2: Medium | M2: Ageing (4-8y) | N2: 64 | O2: 34 | P2: 4 | Q2: 0 | R2: 2.91 | S2: 0.58 | T2: 5 | U2: Force Vectors and VECTOR COMPONENTS in 11 Minutes! - STATICS | V2: Less Boring Lectures | W2: 125000 | X2: 364000 | Y2: =IF(OR(W2="",W2=0,X2=""),"",X2/W2) -> 2.912 | Z2: 5 | AA2: 11:33 | AB2: https://youtu.be/Gz09VNG5wJc | AC2: Planned | AF2: =IF(AC2<>"Published",COUNTIF($AC$2:AC2,"<>Published"),"") -> 1
A3: 2 | B3: =ROUNDUP(A3/3,0) -> 1 | C3: Phase 1: mechanics + E&M alternate, textbook order (two playlists) | D3: EM-01 | E3: Electricity & Magnetism | F3: OpenStax University Physics Vol. 2 (CC BY 4.0) §5.1-5.3 Coulomb's law | G3: Coulomb's law and superposition: solving multi-charge problems | H3: Derivation / worked problem | I3: 6-8 min | J3: ME-01 | K3: A-level/IB/AP | L3: Medium | M3: Stale (median outlier age 8y+) | N3: 87 | O3: 41 | P3: 7 | Q3: 0 | R3: 3.02 | S3: 0.72 | T3: 13 | U3: Coulomb's Law | V3: uclaphysicsvideo | W3: 60300 | X3: 182000 | Y3: =IF(OR(W3="",W3=0,X3=""),"",X3/W3) -> 3.0182421 | Z3: 16 | AA3: 4:17 | AB3: https://youtu.be/B5LVoU_a08c | AC3: Planned | AF3: =IF(AC3<>"Published",COUNTIF($AC$2:AC3,"<>Published"),"") -> 2
A4: 3 | B4: =ROUNDUP(A4/3,0) -> 1 | C4: Phase 1: mechanics + E&M alternate, textbook order (two playlists) | D4: ME-02 | E4: Mechanics | F4: OpenStax University Physics Vol. 1 (CC BY 4.0) Ch.3 Motion along a straight line | G4: The kinematic equations: where they come from (not just how to use them) | H4: Derivation / worked problem | I4: 6-8 min | J4: None | K4: A-level/IB/AP/KCSE | L4: High | M4: Stale (median outlier age 8y+) | N4: 48 | O4: 30 | P4: 9 | Q4: 2 | R4: 35.24 | S4: 3.52 | T4: 9 | U4: Equations of motion (Higher Physics) | V4: Mr Smith's Physics online | W4: 27500 | X4: 969000 | Y4: =IF(OR(W4="",W4=0,X4=""),"",X4/W4) -> 35.236364 | Z4: 10 | AA4: 9:11 | AB4: https://youtu.be/WJN_F3PYp58 | AC4: Planned | AF4: =IF(AC4<>"Published",COUNTIF($AC$2:AC4,"<>Published"),"") -> 3
A5: 4 | B5: =ROUNDUP(A5/3,0) -> 2 | C5: Phase 1: mechanics + E&M alternate, textbook order (two playlists) | D5: EM-02 | E5: Electricity & Magnetism | F5: OpenStax University Physics Vol. 2 (CC BY 4.0) §5.4-5.7 Electric field | G5: The electric field: what it is, and the field of a line and a ring of charge | H5: Derivation / worked problem | I5: 7-9 min | J5: EM-01 | K5: A-level/IB/AP | L5: Medium | M5: Stale (median outlier age 8y+) | N5: 228 | O5: 58 | P5: 28 | Q5: 0 | R5: 5.1 | S5: 0.7 | T5: 10.5 | U5: The Electric Field Due to a Line of Charge | V5: lasseviren1 | W5: 76600 | X5: 391000 | Y5: =IF(OR(W5="",W5=0,X5=""),"",X5/W5) -> 5.1044386 | Z5: 16 | AA5: 10:01 | AB5: https://youtu.be/WmZ3G2DWHlg | AC5: Planned | AF5: =IF(AC5<>"Published",COUNTIF($AC$2:AC5,"<>Published"),"") -> 4
A6: 5 | B6: =ROUNDUP(A6/3,0) -> 2 | C6: Phase 1: mechanics + E&M alternate, textbook order (two playlists) | D6: ME-03 | E6: Mechanics | F6: OpenStax University Physics Vol. 1 (CC BY 4.0) §3.5 Free fall | G6: Free fall and the velocity-time graph, visualised | H6: Explainer (one concept, one animation) | I6: 5-7 min | J6: ME-02 | K6: A-level/IB/AP/KCSE | L6: High | M6: Stale (median outlier age 8y+) | N6: 59 | O6: 33 | P6: 12 | Q6: 2 | R6: 23.33 | S6: 1.94 | T6: 13.5 | U6: Distance (position) to Velocity Time Graph Physics Help | V6: Physicshelp Canada | W6: 61400 | X6: 924000 | Y6: =IF(OR(W6="",W6=0,X6=""),"",X6/W6) -> 15.04886 | Z6: 15 | AA6: 8:08 | AB6: https://youtu.be/EZXLkAYjmR0 | AC6: Planned | AF6: =IF(AC6<>"Published",COUNTIF($AC$2:AC6,"<>Published"),"") -> 5
A7: 6 | B7: =ROUNDUP(A7/3,0) -> 2 | C7: Phase 1: mechanics + E&M alternate, textbook order (two playlists) | D7: EM-03 | E7: Electricity & Magnetism | F7: OpenStax University Physics Vol. 2 (CC BY 4.0) Ch.6 Gauss's law | G7: Gauss's law: an intuitive picture, then the sphere, cylinder and plane | H7: Derivation / worked problem | I7: 7-9 min | J7: EM-02, MM-03 | K7: A-level/IB/AP | L7: Medium | M7: Stale (median outlier age 8y+) | N7: 69 | O7: 25 | P7: 16 | Q7: 1 | R7: 9.67 | S7: 1.25 | T7: 16 | U7: Gauss's Law Basics | V7: lasseviren1 | W7: 76600 | X7: 741000 | Y7: =IF(OR(W7="",W7=0,X7=""),"",X7/W7) -> 9.6736292 | Z7: 16 | AA7: 10:01 | AB7: https://youtu.be/QNIJC1emss8 | AC7: Planned | AF7: =IF(AC7<>"Published",COUNTIF($AC$2:AC7,"<>Published"),"") -> 6
A8: 7 | B8: =ROUNDUP(A8/3,0) -> 3 | C8: Phase 1: mechanics + E&M alternate, textbook order (two playlists) | D8: ME-04 | E8: Mechanics | F8: OpenStax University Physics Vol. 1 (CC BY 4.0) §4.3 Projectile motion | G8: Projectile motion from zero: one method for every question | H8: Derivation / worked problem | I8: 7-9 min | J8: ME-02 | K8: A-level/IB/AP/KCSE | L8: High | M8: Ageing (4-8y) | N8: 132 | O8: 49 | P8: 30 | Q8: 5 | R8: 41.15 | S8: 41.05 | T8: 6 | U8: Projectile Motion: 3 methods to answer ALL questions! | V8: That Physics Guy | W8: 24300 | X8: 1000000 | Y8: =IF(OR(W8="",W8=0,X8=""),"",X8/W8) -> 41.152263 | Z8: 2 | AA8: 15:37 | AB8: https://youtu.be/1eRimU5befo | AC8: Planned | AF8: =IF(AC8<>"Published",COUNTIF($AC$2:AC8,"<>Published"),"") -> 7
A9: 8 | B9: =ROUNDUP(A9/3,0) -> 3 | C9: Phase 1: mechanics + E&M alternate, textbook order (two playlists) | D9: EM-04 | E9: Electricity & Magnetism | F9: OpenStax University Physics Vol. 2 (CC BY 4.0) Ch.7 Electric potential | G9: Electric potential vs potential energy vs voltage: the three things students mix up | H9: Explainer (one concept, one animation) | I9: 6-8 min | J9: EM-02 | K9: A-level/IB/AP | L9: Medium | M9: Stale (median outlier age 8y+) | N9: 120 | O9: 45 | P9: 8 | Q9: 0 | R9: 4.92 | S9: 0.79 | T9: 11.5 | U9: What is an Electric Potential ? | V9: Physics Made Easy | W9: 74100 | X9: 330000 | Y9: =IF(OR(W9="",W9=0,X9=""),"",X9/W9) -> 4.4534413 | Z9: 6 | AA9: 8:35 | AB9: https://youtu.be/j3GrOKre__0 | AC9: Planned | AF9: =IF(AC9<>"Published",COUNTIF($AC$2:AC9,"<>Published"),"") -> 8
A10: 9 | B10: =ROUNDUP(A10/3,0) -> 3 | C10: Phase 1: mechanics + E&M alternate, textbook order (two playlists) | D10: ME-05 | E10: Mechanics | F10: OpenStax University Physics Vol. 1 (CC BY 4.0) §4.4 Uniform circular motion | G10: Why circular motion needs a force: centripetal acceleration derived | H10: Derivation / worked problem | I10: 6-8 min | J10: ME-01 | K10: A-level/IB/AP | L10: High | M10: Stale (median outlier age 8y+) | N10: 107 | O10: 43 | P10: 18 | Q10: 1 | R10: 26.38 | S10: 5.28 | T10: 10 | U10: What is Centripetal force? | V10: Sabins | W10: 79600 | X10: 2100000 | Y10: =IF(OR(W10="",W10=0,X10=""),"",X10/W10) -> 26.38191 | Z10: 5 | AA10: 6:24 | AB10: https://youtu.be/5vtH1uBaoBY | AC10: Planned | AF10: =IF(AC10<>"Published",COUNTIF($AC$2:AC10,"<>Published"),"") -> 9
A11: 10 | B11: =ROUNDUP(A11/3,0) -> 4 | C11: Phase 1: mechanics + E&M alternate, textbook order (two playlists) | D11: EM-05 | E11: Electricity & Magnetism | F11: OpenStax University Physics Vol. 2 (CC BY 4.0) Ch.8 Capacitance | G11: Capacitors: capacitance, stored energy and dielectrics, derived | H11: Derivation / worked problem | I11: 7-9 min | J11: EM-04 | K11: A-level/IB/AP | L11: High | M11: Ageing (4-8y) | N11: 286 | O11: 74 | P11: 18 | Q11: 4 | R11: 11.11 | S11: 3.13 | T11: 7 | U11: A.C. Circuits : Phasors, Impedance, Fourier Transform, and how Inductors and Capacitors work | V11: TheSiGuy | W11: 24900 | X11: 234000 | Y11: =IF(OR(W11="",W11=0,X11=""),"",X11/W11) -> 9.3975904 | Z11: 3 | AA11: 17:23 | AB11: https://youtu.be/cy_KI_FiS7I | AC11: Planned | AF11: =IF(AC11<>"Published",COUNTIF($AC$2:AC11,"<>Published"),"") -> 10
A12: 11 | B12: =ROUNDUP(A12/3,0) -> 4 | C12: Phase 1: mechanics + E&M alternate, textbook order (two playlists) | D12: ME-06 | E12: Mechanics | F12: OpenStax University Physics Vol. 1 (CC BY 4.0) §4.5 Relative motion | G12: Relative velocity: the boat, the river and the frame of reference | H12: Explainer (one concept, one animation) | I12: 5-7 min | J12: ME-01 | K12: A-level/IB/AP | L12: Medium | M12: Stale (median outlier age 8y+) | N12: 41 | O12: 25 | P12: 6 | Q12: 1 | R12: 5.95 | S12: 1.49 | T12: 15.5 | U12: Introduction to Relative motion! | V12: Sabins | W12: 79600 | X12: 474000 | Y12: =IF(OR(W12="",W12=0,X12=""),"",X12/W12) -> 5.9547739 | Z12: 4 | AA12: 2:04 | AB12: https://youtu.be/oKvscIVhelo | AC12: Planned | AF12: =IF(AC12<>"Published",COUNTIF($AC$2:AC12,"<>Published"),"") -> 11
A13: 12 | B13: =ROUNDUP(A13/3,0) -> 4 | C13: Phase 1: mechanics + E&M alternate, textbook order (two playlists) | D13: EM-06 | E13: Electricity & Magnetism | F13: OpenStax University Physics Vol. 2 (CC BY 4.0) Ch.9 Current & resistance | G13: Current, drift velocity and Ohm's law from the electron's point of view | H13: Explainer (one concept, one animation) | I13: 6-8 min | J13: EM-04 | K13: A-level/IB/AP/KCSE | L13: High | M13: Stale (median outlier age 8y+) | N13: 189 | O13: 68 | P13: 13 | Q13: 3 | R13: 14.36 | S13: 7.07 | T13: 11 | U13: Resistors Explained & Ohm's Law Made Simple! | What Are Resistors? & How Do Resistors Work? | V13: Engineeringness | W13: 72600 | X13: 513000 | Y13: =IF(OR(W13="",W13=0,X13=""),"",X13/W13) -> 7.0661157 | Z13: 1 | AA13: 4:05 | AB13: https://youtu.be/x6jajfprWZo | AC13: Planned | AF13: =IF(AC13<>"Published",COUNTIF($AC$2:AC13,"<>Published"),"") -> 12
... A33: 32 | B33: =ROUNDUP(A33/3,0) -> 11 | C33: Phase 2: mechanics / E&M / waves / thermo rotation | D33: TH-02 | E33: Thermodynamics | F33: OpenStax University Physics Vol. 2 (CC BY 4.0) Ch.2 Kinetic theory | G33: Kinetic theory: deriving pressure and temperature from bouncing molecules | H33: Derivation / worked problem | I33: 7-9 min | J33: ME-16 | K33: A-level/IB/AP | L33: Medium | M33: Ageing (4-8y) | N33: 92 | O33: 37 | P33: 8 | Q33: 0 | R33: 6.92 | S33: 1.38 | T33: 6 | U33: Quantitative Description of Isothermal (Constant Temperature) Process with Ideal Gas on P-V Diagram | V33: Elucyda | W33: 21500 | X33: 55000 | Y33: =IF(OR(W33="",W33=0,X33=""),"",X33/W33) -> 2.5581395 | Z33: 6 | AA33: 10:23 | AB33: https://youtu.be/kvYFNs6In6Y | AC33: Planned | AF33: =IF(AC33<>"Published",COUNTIF($AC$2:AC33,"<>Published"),"") -> 32
A34: 33 | B34: =ROUNDUP(A34/3,0) -> 11 | C34: Phase 2: mechanics / E&M / waves / thermo rotation | D34: ME-15 | E34: Mechanics | F34: OpenStax University Physics Vol. 1 (CC BY 4.0) §8.4 Potential energy diagrams | G34: Potential energy diagrams: reading stability off a curve | H34: Explainer (one concept, one animation) | I34: 5-7 min | J34: ME-14 | K34: University | L34: Low | M34: - | N34: 9 | O34: 4 | P34: 0 | Q34: 0 | R34: 0.01 | S34: 0 | U34: Understanding potential energy diagrams - Physics | V34: Brief Physics | W34: 1640 | X34: 19 | Y34: =IF(OR(W34="",W34=0,X34=""),"",X34/W34) -> 0.011585366 | Z34: 0.25 | AA34: 13:07 | AB34: https://youtu.be/2fkkWihW2Uk | AC34: Planned | AF34: =IF(AC34<>"Published",COUNTIF($AC$2:AC34,"<>Published"),"") -> 33
A35: 34 | B35: =ROUNDUP(A35/3,0) -> 12 | C35: Phase 2: mechanics / E&M / waves / thermo rotation | D35: EM-15 | E35: Electricity & Magnetism | F35: OpenStax University Physics Vol. 2 (CC BY 4.0) §13.6-13.7 Eddy currents & generators | G35: Generators, back emf and eddy currents: induction in the real world | H35: Explainer (one concept, one animation) | I35: 6-8 min | J35: EM-13 | K35: A-level/IB/KCSE | L35: Medium | M35: Stale (median outlier age 8y+) | N35: 46 | O35: 31 | P35: 5 | Q35: 0 | R35: 4.33 | S35: 0.67 | T35: 9 | U35: Electric Generator Lenz's Law Part 1 Left or Right Hand Rule Physics Lesson | V35: Physicshelp Canada | W35: 61400 | X35: 266000 | Y35: =IF(OR(W35="",W35=0,X35=""),"",X35/W35) -> 4.3322476 | Z35: 14 | AA35: 5:03 | AB35: https://youtu.be/8FXPmYGIOs4 | AC35: Planned | AF35: =IF(AC35<>"Published",COUNTIF($AC$2:AC35,"<>Published"),"") -> 34
A36: 35 | B36: =ROUNDUP(A36/3,0) -> 12 | C36: Phase 2: mechanics / E&M / waves / thermo rotation | D36: WO-03 | E36: Fluids, Oscillations, Waves & Sound | F36: OpenStax University Physics Vol. 1 (CC BY 4.0) §14.7 Viscosity & turbulence | G36: Viscosity, Reynolds number and the onset of turbulence | H36: Explainer (one concept, one animation) | I36: 6-8 min | J36: WO-02 | K36: University | L36: High | M36: Ageing (4-8y) | N36: 41 | O36: 23 | P36: 5 | Q36: 2 | R36: 50 | S36: 6.25 | T36: 6 | U36: Description and Derivation of the Navier-Stokes Equations | V36: LearnMechE | W36: 8480 | X36: 424000 | Y36: =IF(OR(W36="",W36=0,X36=""),"",X36/W36) -> 50 | Z36: 8 | AA36: 11:18 | AB36: https://youtu.be/NjoMoH51UZc | AC36: Planned | AF36: =IF(AC36<>"Published",COUNTIF($AC$2:AC36,"<>Published"),"") -> 35
A37: 36 | B37: =ROUNDUP(A37/3,0) -> 12 | C37: Phase 2: mechanics / E&M / waves / thermo rotation | D37: TH-03 | E37: Thermodynamics | F37: OpenStax University Physics Vol. 2 (CC BY 4.0) §2.4 Maxwell-Boltzmann | G37: The Maxwell-Boltzmann distribution: where the curve comes from | H37: Derivation / worked problem | I37: 7-9 min | J37: TH-02 | K37: A-level/University | L37: Medium | M37: Ageing (4-8y) | N37: 18 | O37: 11 | P37: 3 | Q37: 0 | R37: 3.23 | S37: 0.83 | T37: 5 | U37: Statistical Physics - The Boltzmann Distribution | V37: Pazzy Boardman | W37: 7120 | X37: 23000 | Y37: =IF(OR(W37="",W37=0,X37=""),"",X37/W37) -> 3.2303371 | Z37: 7 | AA37: 35:30 | AB37: https://youtu.be/guL3KKLsqsw | AC37: Planned | AF37: =IF(AC37<>"Published",COUNTIF($AC$2:AC37,"<>Published"),"") -> 36
A38: 37 | B38: =ROUNDUP(A38/3,0) -> 13 | C38: Phase 2: mechanics / E&M / waves / thermo rotation | D38: ME-16 | E38: Mechanics | F38: OpenStax University Physics Vol. 1 (CC BY 4.0) Ch.9 Momentum & impulse | G38: Momentum and impulse: why airbags work (F Δt = Δp) | H38: Explainer (one concept, one animation) | I38: 5-7 min | J38: ME-07 | K38: A-level/IB/AP/KCSE | L38: High | M38: Stale (median outlier age 8y+) | N38: 200 | O38: 79 | P38: 18 | Q38: 1 | R38: 10.15 | S38: 1.83 | T38: 13 | U38: Collisions and Momentum Conservation | V38: James Dann, Ph.D. | W38: 13700 | X38: 139000 | Y38: =IF(OR(W38="",W38=0,X38=""),"",X38/W38) -> 10.145985 | Z38: 16 | AA38: 5:59 | AB38: https://youtu.be/HdjxMw9bumI | AC38: Planned | AF38: =IF(AC38<>"Published",COUNTIF($AC$2:AC38,"<>Published"),"") -> 37
A39: 38 | B39: =ROUNDUP(A39/3,0) -> 13 | C39: Phase 2: mechanics / E&M / waves / thermo rotation | D39: EM-16 | E39: Electricity & Magnetism | F39: OpenStax University Physics Vol. 2 (CC BY 4.0) Ch.14 Inductance | G39: Inductance: self-inductance, the RL circuit and energy in a magnetic field | H39: Derivation / worked problem | I39: 7-9 min | J39: EM-13 | K39: A-level/IB/University | L39: High | M39: Stale (median outlier age 8y+) | N39: 69 | O39: 30 | P39: 10 | Q39: 3 | R39: 10.28 | S39: 3.13 | T39: 16 | U39: Understanding Inductors! | V39: Sabins | W39: 79600 | X39: 818000 | Y39: =IF(OR(W39="",W39=0,X39=""),"",X39/W39) -> 10.276382 | Z39: 5 | AA39: 4:24 | AB39: https://youtu.be/d73e3QiMdSU | AC39: Planned | AF39: =IF(AC39<>"Published",COUNTIF($AC$2:AC39,"<>Published"),"") -> 38
A40: 39 | B40: =ROUNDUP(A40/3,0) -> 13 | C40: Phase 2: mechanics / E&M / waves / thermo rotation | D40: WO-04 | E40: Fluids, Oscillations, Waves & Sound | F40: OpenStax University Physics Vol. 1 (CC BY 4.0) §15.1-15.2 Simple harmonic motion | G40: Simple harmonic motion: the general equation, derived and animated | H40: Derivation / worked problem | I40: 7-9 min | J40: ME-14 | K40: A-level/IB/AP | L40: High | M40: Stale (median outlier age 8y+) | N40: 121 | O40: 36 | P40: 14 | Q40: 2 | R40: 61.81 | S40: 12.36 | T40: 10.5 | U40: Introduction to Simple Harmonic Motion (SHM) | General Equation and Derivation | V40: Physix Daily | W40: 2540 | X40: 157000 | Y40: =IF(OR(W40="",W40=0,X40=""),"",X40/W40) -> 61.811024 | Z40: 5 | AA40: 6:46 | AB40: https://youtu.be/8bTvHbrJ8Cg | AC40: Planned | AF40: =IF(AC40<>"Published",COUNTIF($AC$2:AC40,"<>Published"),"") -> 39
A41: 40 | B41: =ROUNDUP(A41/3,0) -> 14 | C41: Phase 2: mechanics / E&M / waves / thermo rotation | D41: TH-04 | E41: Thermodynamics | F41: OpenStax University Physics Vol. 2 (CC BY 4.0) Ch.3 First law | G41: The first law of thermodynamics and the four named processes on a PV diagram | H41: Explainer (one concept, one animation) | I41: 7-9 min | J41: TH-02 | K41: A-level/IB/AP | L41: High | M41: Ageing (4-8y) | N41: 74 | O41: 32 | P41: 7 | Q41: 1 | R41: 9.06 | S41: 1.81 | T41: 6 | U41: FIRST LAW OF THERMODYNAMICS | Easy and Short | V41: EarthPen | W41: 94100 | X41: 371000 | Y41: =IF(OR(W41="",W41=0,X41=""),"",X41/W41) -> 3.9426142 | Z41: 7 | AA41: 2:09 | AB41: https://youtu.be/Bz6vexpZItw | AC41: Planned | AF41: =IF(AC41<>"Published",COUNTIF($AC$2:AC41,"<>Published"),"") -> 40
A42: 41 | B42: =ROUNDUP(A42/3,0) -> 14 | C42: Phase 2: mechanics / E&M / waves / thermo rotation | D42: ME-17 | E42: Mechanics | F42: OpenStax University Physics Vol. 1 (CC BY 4.0) §9.4-9.6 Collisions | G42: Elastic vs inelastic collisions in 1D and 2D: one method | H42: Derivation / worked problem | I42: 7-9 min | J42: ME-16 | K42: A-level/IB/AP | L42: Medium | M42: Stale (median outlier age 8y+) | N42: 86 | O42: 36 | P42: 8 | Q42: 0 | R42: 10.15 | S42: 0.63 | T42: 12.5 | U42: Collisions and Momentum Conservation | V42: James Dann, Ph.D. | W42: 13700 | X42: 139000 | Y42: =IF(OR(W42="",W42=0,X42=""),"",X42/W42) -> 10.145985 | Z42: 16 | AA42: 5:59 | AB42: https://youtu.be/HdjxMw9bumI | AC42: Planned | AF42: =IF(AC42<>"Published",COUNTIF($AC$2:AC42,"<>Published"),"") -> 41
A43: 42 | B43: =ROUNDUP(A43/3,0) -> 14 | C43: Phase 2: mechanics / E&M / waves / thermo rotation | D43: EM-17 | E43: Electricity & Magnetism | F43: OpenStax University Physics Vol. 2 (CC BY 4.0) §14.5-14.6 LC & RLC | G43: LC oscillations: a circuit that behaves exactly like a mass on a spring | H43: Explainer (one concept, one animation) | I43: 6-8 min | J43: EM-16, WO-04 | K43: A-level/IB/University | L43: Medium | M43: Stale (median outlier age 8y+) | N43: 28 | O43: 14 | P43: 3 | Q43: 0 | R43: 2.42 | S43: 0.25 | T43: 10 | U43: The LC Circuit | V43: lasseviren1 | W43: 76600 | X43: 185000 | Y43: =IF(OR(W43="",W43=0,X43=""),"",X43/W43) -> 2.4151436 | Z43: 16 | AA43: 10:18 | AB43: https://youtu.be/v3-HwZMThzQ | AC43: Planned | AF43: =IF(AC43<>"Published",COUNTIF($AC$2:AC43,"<>Published"),"") -> 42
A44: 43 | B44: =ROUNDUP(A44/3,0) -> 15 | C44: Phase 2: mechanics / E&M / waves / thermo rotation | D44: WO-05 | E44: Fluids, Oscillations, Waves & Sound | F44: OpenStax University Physics Vol. 1 (CC BY 4.0) §15.3 SHM & circular motion | G44: Why SHM is the shadow of circular motion (phasors explained) | H44: Explainer (one concept, one animation) | I44: 5-7 min | J44: WO-04 | K44: A-level/IB | L44: High | M44: Ageing (4-8y) | N44: 17 | O44: 9 | P44: 2 | Q44: 2 | R44: 21.91 | S44: 3.13 | T44: 6.5 | U44: Introduction to Phasors, Impedance, and AC Circuits | V44: Charles Clayton | W44: 15200 | X44: 333000 | Y44: =IF(OR(W44="",W44=0,X44=""),"",X44/W44) -> 21.907895 | Z44: 10 | AA44: 3:53 | AB44: https://youtu.be/ZSDpIpnlTbY | AC44: Planned | AF44: =IF(AC44<>"Published",COUNTIF($AC$2:AC44,"<>Published"),"") -> 43
A45: 44 | B45: =ROUNDUP(A45/3,0) -> 15 | C45: Phase 2: mechanics / E&M / waves / thermo rotation | D45: TH-05 | E45: Thermodynamics | F45: OpenStax University Physics Vol. 2 (CC BY 4.0) §3.5 Heat capacities | G45: Why Cp is bigger than Cv (and the equipartition theorem) | H45: Derivation / worked problem | I45: 6-8 min | J45: TH-04 | K45: University | L45: Medium | M45: Ageing (4-8y) | N45: 76 | O45: 39 | P45: 5 | Q45: 1 | R45: 4.67 | S45: 1.17 | T45: 7 | U45: Specific Heat and Latent Heat | V45: Jennifer Cash | W45: 13200 | X45: 47000 | Y45: =IF(OR(W45="",W45=0,X45=""),"",X45/W45) -> 3.5606061 | Z45: 12 | AA45: 4:30 | AB45: https://youtu.be/AVYbTI73wSU | AC45: Planned | AF45: =IF(AC45<>"Published",COUNTIF($AC$2:AC45,"<>Published"),"") -> 44
A46: 45 | B46: =ROUNDUP(A46/3,0) -> 15 | C46: Phase 2: mechanics / E&M / waves / thermo rotation | D46: ME-18 | E46: Mechanics | F46: OpenStax University Physics Vol. 1 (CC BY 4.0) §9.6 Centre of mass | G46: Centre of mass: why the system moves as if it were one particle | H46: Explainer (one concept, one animation) | I46: 5-7 min | J46: ME-16 | K46: A-level/IB/AP | L46: Medium | M46: Stale (median outlier age 8y+) | N46: 43 | O46: 27 | P46: 5 | Q46: 0 | R46: 9.03 | S46: 0.82 | T46: 11 | U46: Center of Mass Demo | V46: Astronomy 1101: From Planets to the Cosmos Online | W46: 21600 | X46: 195000 | Y46: =IF(OR(W46="",W46=0,X46=""),"",X46/W46) -> 9.0277778 | Z46: 11 | AA46: 3:07 | AB46: https://youtu.be/OcI2GPB4y6A | AC46: Planned | AF46: =IF(AC46<>"Published",COUNTIF($AC$2:AC46,"<>Published"),"") -> 45
... A49: 48 | B49: =ROUNDUP(A49/3,0) -> 16 | C49: Phase 2: mechanics / E&M / waves / thermo rotation | D49: TH-06 | E49: Thermodynamics | F49: OpenStax University Physics Vol. 2 (CC BY 4.0) §4.5 Carnot cycle | G49: The Carnot cycle and the maximum efficiency of any engine | H49: Derivation / worked problem | I49: 7-9 min | J49: TH-04 | K49: A-level/IB/AP | L49: High | M49: Ageing (4-8y) | N49: 31 | O49: 17 | P49: 3 | Q49: 2 | R49: 12.91 | S49: 2.15 | T49: 6 | U49: Carnot Cycle - An Ideal Heat Engine | V49: Fizică | W49: 42300 | X49: 546000 | Y49: =IF(OR(W49="",W49=0,X49=""),"",X49/W49) -> 12.907801 | Z49: 6 | AA49: 4:40 | AB49: https://youtu.be/NasmLQOf30s | AC49: Planned | AF49: =IF(AC49<>"Published",COUNTIF($AC$2:AC49,"<>Published"),"") -> 48
A50: 49 | B50: =ROUNDUP(A50/3,0) -> 17 | C50: Phase 3: optics, modern physics and maths methods join; anchors as courses complete | D50: ME-19 | E50: Mechanics | F50: OpenStax University Physics Vol. 1 (CC BY 4.0) §9.7 Rocket propulsion | G50: The rocket equation, derived from momentum conservation | H50: Derivation / worked problem | I50: 6-8 min | J50: ME-16 | K50: University | L50: Medium | M50: - | N50: 4 | O50: 4 | P50: 0 | Q50: 0 | R50: 1.59 | S50: 1.73 | U50: Understanding rocket propulsion - Physics | V50: Brief Physics | W50: 1640 | X50: 2600 | Y50: =IF(OR(W50="",W50=0,X50=""),"",X50/W50) -> 1.5853659 | Z50: 0.92 | AA50: 13:20 | AB50: https://youtu.be/CrWSFL01qV0 | AC50: Planned | AF50: =IF(AC50<>"Published",COUNTIF($AC$2:AC50,"<>Published"),"") -> 49
A51: 50 | B51: =ROUNDUP(A51/3,0) -> 17 | C51: Phase 3: optics, modern physics and maths methods join; anchors as courses complete | D51: EM-19 | E51: Electricity & Magnetism | F51: OpenStax University Physics Vol. 2 (CC BY 4.0) §15.6 Transformers | G51: How a transformer works (and why the grid runs on AC) | H51: Explainer (one concept, one animation) | I51: 5-7 min | J51: EM-13 | K51: A-level/IB/KCSE | L51: Medium | M51: Stale (median outlier age 8y+) | N51: 38 | O51: 25 | P51: 4 | Q51: 0 | R51: 9.03 | S51: 0.82 | T51: 9.5 | U51: Transformers explained | V51: Cowen Physics | W51: 18600 | X51: 168000 | Y51: =IF(OR(W51="",W51=0,X51=""),"",X51/W51) -> 9.0322581 | Z51: 11 | AA51: 5:41 | AB51: https://youtu.be/b6uru1lYUeI | AC51: Planned | AF51: =IF(AC51<>"Published",COUNTIF($AC$2:AC51,"<>Published"),"") -> 50
A52: 51 | B52: =ROUNDUP(A52/3,0) -> 17 | C52: Phase 3: optics, modern physics and maths methods join; anchors as courses complete | D52: WO-07 | E52: Fluids, Oscillations, Waves & Sound | F52: OpenStax University Physics Vol. 1 (CC BY 4.0) §15.5 Damped oscillations | G52: Damped oscillations: under-, over- and critically damped, visualised | H52: Derivation / worked problem | I52: 6-8 min | J52: WO-04 | K52: A-level/IB | L52: High | M52: Stale (median outlier age 8y+) | N52: 41 | O52: 21 | P52: 2 | Q52: 1 | R52: 342.37 | S52: 31.12 | T52: 8 | U52: Damped Oscillatory Motion | V52: Rebecca Koehler | W52: 295 | X52: 101000 | Y52: =IF(OR(W52="",W52=0,X52=""),"",X52/W52) -> 342.37288 | Z52: 11 | AA52: 2:57 | AB52: https://youtu.be/sP1DzhT8Vzo | AC52: Planned | AF52: =IF(AC52<>"Published",COUNTIF($AC$2:AC52,"<>Published"),"") -> 51
A53: 52 | B53: =ROUNDUP(A53/3,0) -> 18 | C53: Phase 3: optics, modern physics and maths methods join; anchors as courses complete | D53: TH-07 | E53: Thermodynamics | F53: OpenStax University Physics Vol. 2 (CC BY 4.0) §4.7-4.8 Entropy | G53: Entropy: from dQ/T to counting microstates (S = k ln W) | H53: Explainer (one concept, one animation) | I53: 7-9 min | J53: TH-06 | K53: A-level/IB/University | L53: High | M53: Ageing (4-8y) | N53: 153 | O53: 60 | P53: 8 | Q53: 2 | R53: 9.23 | S53: 5.14 | T53: 6.5 | U53: How Entropy Was Discovered | V53: Abide By Reason | W53: 130000 | X53: 1200000 | Y53: =IF(OR(W53="",W53=0,X53=""),"",X53/W53) -> 9.2307692 | Z53: 0.25 | AA53: 20:14 | AB53: https://youtu.be/WI0ZLkxJ6Zk | AC53: Planned | AF53: =IF(AC53<>"Published",COUNTIF($AC$2:AC53,"<>Published"),"") -> 52
A54: 53 | B54: =ROUNDUP(A54/3,0) -> 18 | C54: Phase 3: optics, modern physics and maths methods join; anchors as courses complete | D54: TH-08 | E54: Thermodynamics | F54: OpenStax University Physics Vol. 2 (CC BY 4.0) Ch.1-4 (whole) | G54: ALL of Thermodynamics in 12 minutes | H54: Anchor (ALL of…) | I54: 12 min | J54: TH-01…TH-07 | K54: A-level/IB/AP | L54: High | M54: Fresh (<4y) | N54: 12 | O54: 5 | P54: 2 | Q54: 1 | R54: 15.62 | S54: 15.62 | T54: 2.5 | U54: All of Thermodynamics Explained in 11 Minutes | V54: Easy Explained 2.0 | W54: 9220 | X54: 144000 | Y54: =IF(OR(W54="",W54=0,X54=""),"",X54/W54) -> 15.618221 | Z54: 1 | AA54: 11:39 | AB54: https://youtu.be/0a8gjbn33rM | AC54: Planned | AF54: =IF(AC54<>"Published",COUNTIF($AC$2:AC54,"<>Published"),"") -> 53
A55: 54 | B55: =ROUNDUP(A55/3,0) -> 18 | C55: Phase 3: optics, modern physics and maths methods join; anchors as courses complete | D55: OP-01 | E55: Optics | F55: OpenStax University Physics Vol. 3 (CC BY 4.0) §1.3-1.4 Refraction | G55: Snell's law and total internal reflection (how optical fibre works) | H55: Derivation / worked problem | I55: 6-8 min | J55: WO-09 | K55: A-level/IB/AP/KCSE | L55: High | M55: Stale (median outlier age 8y+) | N55: 92 | O55: 46 | P55: 7 | Q55: 2 | R55: 13.39 | S55: 2.36 | T55: 12 | U55: Total Internal Reflection Demo: Optical Fibers | V55: Physics Demos | W55: 112000 | X55: 1500000 | Y55: =IF(OR(W55="",W55=0,X55=""),"",X55/W55) -> 13.392857 | Z55: 10 | AA55: 2:21 | AB55: https://youtu.be/Lic3gCS_bKo | AC55: Planned | AF55: =IF(AC55<>"Published",COUNTIF($AC$2:AC55,"<>Published"),"") -> 54
A56: 55 | B56: =ROUNDUP(A56/3,0) -> 19 | C56: Phase 3: optics, modern physics and maths methods join; anchors as courses complete | D56: MP-01 | E56: Modern Physics (relativity, quantum, nuclear) | F56: OpenStax University Physics Vol. 3 (CC BY 4.0) §5.1-5.4 Special relativity I | G56: Time dilation and length contraction from two postulates (the light clock) | H56: Derivation / worked problem | I56: 7-9 min | J56: ME-06 | K56: A-level/IB/AP | L56: High | M56: Fresh (<4y) | N56: 165 | O56: 49 | P56: 10 | Q56: 3 | R56: 6.72 | S56: 1.96 | T56: 3 | U56: Time Dilation Example Problem | V56: James Dann, Ph.D. | W56: 13700 | X56: 92000 | Y56: =IF(OR(W56="",W56=0,X56=""),"",X56/W56) -> 6.7153285 | Z56: 16 | AA56: 3:39 | AB56: https://youtu.be/SchfetsZysM | AC56: Planned | AF56: =IF(AC56<>"Published",COUNTIF($AC$2:AC56,"<>Published"),"") -> 55
A57: 56 | B57: =ROUNDUP(A57/3,0) -> 19 | C57: Phase 3: optics, modern physics and maths methods join; anchors as courses complete | D57: MM-01 | E57: Maths methods for physics | F57: OpenStax Calculus Vol. 3 Ch.2 Vectors in space (CC BY 4.0) | G57: Vectors, scalars and tensors: what a tensor actually is | H57: Explainer (one concept, one animation) | I57: 7-9 min | J57: ME-01 | K57: University | L57: High | M57: Ageing (4-8y) | N57: 186 | O57: 30 | P57: 15 | Q57: 4 | R57: 72.79 | S57: 20.96 | T57: 4 | U57: What's a Tensor? | V57: Dan Fleisch | W57: 57700 | X57: 4200000 | Y57: =IF(OR(W57="",W57=0,X57=""),"",X57/W57) -> 72.790295 | Z57: 14 | AA57: 12:21 | AB57: https://youtu.be/f5liqUk0ZTw | AC57: Planned | AF57: =IF(AC57<>"Published",COUNTIF($AC$2:AC57,"<>Published"),"") -> 56
A58: 57 | B58: =ROUNDUP(A58/3,0) -> 19 | C58: Phase 3: optics, modern physics and maths methods join; anchors as courses complete | D58: ME-20 | E58: Mechanics | F58: OpenStax University Physics Vol. 1 (CC BY 4.0) §10.1-10.4 Rotational kinematics | G58: Rotational kinematics: every linear equation has a rotational twin | H58: Explainer (one concept, one animation) | I58: 5-7 min | J58: ME-02 | K58: A-level/IB/AP | L58: Medium | M58: Stale (median outlier age 8y+) | N58: 53 | O58: 26 | P58: 6 | Q58: 0 | R58: 2.88 | S58: 0.57 | T58: 12 | U58: Rotational Kinematics | V58: lasseviren1 | W58: 76600 | X58: 149000 | Y58: =IF(OR(W58="",W58=0,X58=""),"",X58/W58) -> 1.9451697 | Z58: 17 | AA58: 9:57 | AB58: https://youtu.be/MKhxRE2apWI | AC58: Planned | AF58: =IF(AC58<>"Published",COUNTIF($AC$2:AC58,"<>Published"),"") -> 57
A59: 58 | B59: =ROUNDUP(A59/3,0) -> 20 | C59: Phase 3: optics, modern physics and maths methods join; anchors as courses complete | D59: ME-21 | E59: Mechanics | F59: OpenStax University Physics Vol. 1 (CC BY 4.0) §10.5 Moment of inertia | G59: Moment of inertia: what it is and how to calculate it for any shape | H59: Derivation / worked problem | I59: 7-9 min | J59: ME-20 | K59: A-level/IB/AP | L59: High | M59: Stale (median outlier age 8y+) | N59: 53 | O59: 30 | P59: 6 | Q59: 2 | R59: 43.14 | S59: 2.88 | T59: 14.5 | U59: Moment of Inertia Explained | V59: James Dann, Ph.D. | W59: 13700 | X59: 591000 | Y59: =IF(OR(W59="",W59=0,X59=""),"",X59/W59) -> 43.138686 | Z59: 15 | AA59: 3:44 | AB59: https://youtu.be/uyU25DdONjo | AC59: Planned | AF59: =IF(AC59<>"Published",COUNTIF($AC$2:AC59,"<>Published"),"") -> 58
A60: 59 | B60: =ROUNDUP(A60/3,0) -> 20 | C60: Phase 3: optics, modern physics and maths methods join; anchors as courses complete | D60: EM-20 | E60: Electricity & Magnetism | F60: OpenStax University Physics Vol. 2 (CC BY 4.0) §16.1 Maxwell's equations | G60: Maxwell's four equations, explained one picture at a time | H60: Explainer (one concept, one animation) | I60: 8-10 min | J60: EM-03, EM-12, EM-13, MM-04 | K60: University | L60: High | M60: Fresh (<4y) | N60: 48 | O60: 32 | P60: 9 | Q60: 2 | R60: 18.79 | S60: 8.44 | T60: 3 | U60: Nobody Explained Maxwell's Equations Like THIS! | V60: Animated Physics | W60: 37100 | X60: 697000 | Y60: =IF(OR(W60="",W60=0,X60=""),"",X60/W60) -> 18.787062 | Z60: 0.25 | AA60: 19:27 | AB60: https://youtu.be/yGWEuxaaMNw | AC60: Planned | AF60: =IF(AC60<>"Published",COUNTIF($AC$2:AC60,"<>Published"),"") -> 59
A61: 60 | B61: =ROUNDUP(A61/3,0) -> 20 | C61: Phase 3: optics, modern physics and maths methods join; anchors as courses complete | D61: WO-08 | E61: Fluids, Oscillations, Waves & Sound | F61: OpenStax University Physics Vol. 1 (CC BY 4.0) §15.6 Forced oscillations & resonance | G61: Resonance: forced oscillations and why the bridge fell | H61: Explainer (one concept, one animation) | I61: 6-8 min | J61: WO-07 | K61: A-level/IB | L61: High | M61: Stale (median outlier age 8y+) | N61: 47 | O61: 32 | P61: 3 | Q61: 0 | R61: 2.13 | S61: 1.71 | T61: 8 | U61: What is resonance in physics? | V61: PhysicsHigh | W61: 146000 | X61: 311000 | Y61: =IF(OR(W61="",W61=0,X61=""),"",X61/W61) -> 2.130137 | Z61: 8 | AA61: 6:08 | AB61: https://youtu.be/ATRzwhk7UvY | AC61: Planned | AF61: =IF(AC61<>"Published",COUNTIF($AC$2:AC61,"<>Published"),"") -> 60
...

Sheet Schedule
A1: Week | B1: Phase | C1: Video 1 | D1: Video 2 | E1: Video 3
A2: 1 | B2: Phase 1: mechanics + E&M alternate, textbook order (two playlists) | C2: ME-01 Vectors: components, dot and cross product in one animation | D2: EM-01 Coulomb's law and superposition: solving multi-charge problems | E2: ME-02 The kinematic equations: where they come from (not just how to use them)
A3: 2 | B3: Phase 1: mechanics + E&M alternate, textbook order (two playlists) | C3: EM-02 The electric field: what it is, and the field of a line and a ring of charge | D3: ME-03 Free fall and the velocity-time graph, visualised | E3: EM-03 Gauss's law: an intuitive picture, then the sphere, cylinder and plane
A4: 3 | B4: Phase 1: mechanics + E&M alternate, textbook order (two playlists) | C4: ME-04 Projectile motion from zero: one method for every question | D4: EM-04 Electric potential vs potential energy vs voltage: the three things students mix up | E4: ME-05 Why circular motion needs a force: centripetal acceleration derived
A5: 4 | B5: Phase 1: mechanics + E&M alternate, textbook order (two playlists) | C5: EM-05 Capacitors: capacitance, stored energy and dielectrics, derived | D5: ME-06 Relative velocity: the boat, the river and the frame of reference | E5: EM-06 Current, drift velocity and Ohm's law from the electron's point of view
A6: 5 | B6: Phase 1: mechanics + E&M alternate, textbook order (two playlists) | C6: ME-07 Newton's three laws, properly: what each one actually says | D6: EM-07 Kirchhoff's rules: solving any circuit with two equations | E6: ME-08 Free-body diagrams: the five-step method that solves any force problem
A7: 6 | B7: Phase 1: mechanics + E&M alternate, textbook order (two playlists) | C7: EM-08 RC circuits: charging and discharging, the differential equation solved visually | D7: ME-09 Inclined planes and pulleys (Atwood machine), step by step | E7: EM-09 The magnetic force on a moving charge and why it does no work
A8: 7 | B8: Phase 1: mechanics + E&M alternate, textbook order (two playlists) | C8: ME-10 Friction: static vs kinetic, and why the static value is a maximum | D8: EM-10 Torque on a current loop in a magnetic field (how a motor works) | E8: ME-11 Banked curves, loops and conical pendulums: centripetal force problems
A9: 8 | B9: Phase 1: mechanics + E&M alternate, textbook order (two playlists) | C9: EM-11 The Biot-Savart law: the field of a straight wire and a loop, derived | D9: ME-12 Drag and terminal velocity: solving the differential equation visually | E9: EM-12 Ampère's law: the wire, the solenoid and the toroid
A10: 9 | B10: Phase 2: mechanics / E&M / waves / thermo rotation | C10: ME-13 Work and the work-energy theorem, derived from F = ma | D10: EM-13 Faraday's law and Lenz's law: electromagnetic induction in one animation | E10: WO-01 Archimedes' principle: the buoyant force derived, not memorised
A11: 10 | B11: Phase 2: mechanics / E&M / waves / thermo rotation | C11: TH-01 Conduction, convection and radiation: the three heat-transfer equations | D11: ME-14 Conservation of energy: the method that skips the forces entirely | E11: EM-14 Motional emf: the sliding rod, derived two ways
A12: 11 | B12: Phase 2: mechanics / E&M / waves / thermo rotation | C12: WO-02 Bernoulli's principle: what it really says (and what the aeroplane myth gets wrong) | D12: TH-02 Kinetic theory: deriving pressure and temperature from bouncing molecules | E12: ME-15 Potential energy diagrams: reading stability off a curve
A13: 12 | B13: Phase 2: mechanics / E&M / waves / thermo rotation | C13: EM-15 Generators, back emf and eddy currents: induction in the real world | D13: WO-03 Viscosity, Reynolds number and the onset of turbulence | E13: TH-03 The Maxwell-Boltzmann distribution: where the curve comes from
... A34: 33 | B34: Phase 4: final anchors and sleep compilations | C34: OP-08 The Rayleigh criterion: why telescopes need to be big | D34: MP-08 The quantum harmonic oscillator and quantum tunnelling | E34: MP-09 The hydrogen atom: quantum numbers, orbitals and spin ½
A35: 34 | B35: Phase 4: final anchors and sleep compilations | C35: MP-10 Radioactive decay, half-life, binding energy, fission and fusion

Sheet By Course
A1: Course | B1: Code | C1: Working title | D1: Source section | E1: Format | F1: Length | G1: Prerequisites | H1: Exam tag | I1: Demand signal | J1: Supply age | K1: Production order
A2: Mechanics | B2: ME-01 | C2: Vectors: components, dot and cross product in one animation | D2: OpenStax University Physics Vol. 1 (CC BY 4.0) Ch.2 Vectors | E2: Explainer (one concept, one animation) | F2: 6-8 min | G2: None | H2: A-level/IB/AP | I2: Medium | J2: Ageing (4-8y) | K2: 1
A3: Mechanics | B3: ME-02 | C3: The kinematic equations: where they come from (not just how to use them) | D3: OpenStax University Physics Vol. 1 (CC BY 4.0) Ch.3 Motion along a straight line | E3: Derivation / worked problem | F3: 6-8 min | G3: None | H3: A-level/IB/AP/KCSE | I3: High | J3: Stale (median outlier age 8y+) | K3: 3
A4: Mechanics | B4: ME-03 | C4: Free fall and the velocity-time graph, visualised | D4: OpenStax University Physics Vol. 1 (CC BY 4.0) §3.5 Free fall | E4: Explainer (one concept, one animation) | F4: 5-7 min | G4: ME-02 | H4: A-level/IB/AP/KCSE | I4: High | J4: Stale (median outlier age 8y+) | K4: 5
A5: Mechanics | B5: ME-04 | C5: Projectile motion from zero: one method for every question | D5: OpenStax University Physics Vol. 1 (CC BY 4.0) §4.3 Projectile motion | E5: Derivation / worked problem | F5: 7-9 min | G5: ME-02 | H5: A-level/IB/AP/KCSE | I5: High | J5: Ageing (4-8y) | K5: 7
A6: Mechanics | B6: ME-05 | C6: Why circular motion needs a force: centripetal acceleration derived | D6: OpenStax University Physics Vol. 1 (CC BY 4.0) §4.4 Uniform circular motion | E6: Derivation / worked problem | F6: 6-8 min | G6: ME-01 | H6: A-level/IB/AP | I6: High | J6: Stale (median outlier age 8y+) | K6: 9
A7: Mechanics | B7: ME-06 | C7: Relative velocity: the boat, the river and the frame of reference | D7: OpenStax University Physics Vol. 1 (CC BY 4.0) §4.5 Relative motion | E7: Explainer (one concept, one animation) | F7: 5-7 min | G7: ME-01 | H7: A-level/IB/AP | I7: Medium | J7: Stale (median outlier age 8y+) | K7: 11
A8: Mechanics | B8: ME-07 | C8: Newton's three laws, properly: what each one actually says | D8: OpenStax University Physics Vol. 1 (CC BY 4.0) Ch.5 Newton's laws | E8: Explainer (one concept, one animation) | F8: 6-8 min | G8: None | H8: A-level/IB/AP/KCSE | I8: High | J8: Stale (median outlier age 8y+) | K8: 13
A9: Mechanics | B9: ME-08 | C9: Free-body diagrams: the five-step method that solves any force problem | D9: OpenStax University Physics Vol. 1 (CC BY 4.0) §5.7 Free-body diagrams | E9: Derivation / worked problem | F9: 6-8 min | G9: ME-07 | H9: A-level/IB/AP | I9: Medium | J9: Stale (median outlier age 8y+) | K9: 15
A10: Mechanics | B10: ME-09 | C10: Inclined planes and pulleys (Atwood machine), step by step | D10: OpenStax University Physics Vol. 1 (CC BY 4.0) §6.1 Inclined planes & pulleys | E10: Derivation / worked problem | F10: 7-9 min | G10: ME-08 | H10: A-level/IB/AP | I10: High | J10: Stale (median outlier age 8y+) | K10: 17
A11: Mechanics | B11: ME-10 | C11: Friction: static vs kinetic, and why the static value is a maximum | D11: OpenStax University Physics Vol. 1 (CC BY 4.0) §6.2 Friction | E11: Explainer (one concept, one animation) | F11: 5-7 min | G11: ME-08 | H11: A-level/IB/AP/KCSE | I11: High | J11: Stale (median outlier age 8y+) | K11: 19
A12: Mechanics | B12: ME-11 | C12: Banked curves, loops and conical pendulums: centripetal force problems | D12: OpenStax University Physics Vol. 1 (CC BY 4.0) §6.3 Centripetal force applications | E12: Derivation / worked problem | F12: 7-9 min | G12: ME-05, ME-08 | H12: A-level/IB/AP | I12: High | J12: Stale (median outlier age 8y+) | K12: 21
A13: Mechanics | B13: ME-12 | C13: Drag and terminal velocity: solving the differential equation visually | D13: OpenStax University Physics Vol. 1 (CC BY 4.0) §6.4 Drag & terminal velocity | E13: Derivation / worked problem | F13: 6-8 min | G13: ME-10 | H13: A-level/IB | I13: Medium | J13: Stale (median outlier age 8y+) | K13: 23
... A101: Cross-course | B101: XC-04 | C101: Everything about Electricity & Magnetism, explained slowly (2 hours, for sleep) | D101: Sleep compilation | E101: Sleep compilation (2 h, explained slowly) | F101: 120 min | G101: EM-01…EM-24 | H101: University | I101: High | J101: Fresh (<4y) | K101: 76

Sheet Progress
A1: Progress
A3: By status | D3: By course | E3: Videos | F3: Published | H3: By demand signal | I3: Videos | K3: By supply age | L3: Videos
A4: Planned | B4: =COUNTIF(Backlog!$AC$2:$AC$101,A4) -> 100 | D4: Mechanics | E4: =COUNTIF(Backlog!$E$2:$E$101,D4) -> 28 | F4: =COUNTIFS(Backlog!$E$2:$E$101,D4,Backlog!$AC$2:$AC$101,"Published") -> 0 | H4: High | I4: =COUNTIF(Backlog!$L$2:$L$101,H4) -> 63 | K4: Stale (median outlier age 8y+) | L4: =COUNTIF(Backlog!$M$2:$M$101,K4) -> 59
A5: Scripted | B5: =COUNTIF(Backlog!$AC$2:$AC$101,A5) -> 0 | D5: Fluids, Oscillations, Waves & Sound | E5: =COUNTIF(Backlog!$E$2:$E$101,D5) -> 12 | F5: =COUNTIFS(Backlog!$E$2:$E$101,D5,Backlog!$AC$2:$AC$101,"Published") -> 0 | H5: Medium | I5: =COUNTIF(Backlog!$L$2:$L$101,H5) -> 35 | K5: Ageing (4-8y) | L5: =COUNTIF(Backlog!$M$2:$M$101,K5) -> 29
A6: Audio done | B6: =COUNTIF(Backlog!$AC$2:$AC$101,A6) -> 0 | D6: Thermodynamics | E6: =COUNTIF(Backlog!$E$2:$E$101,D6) -> 8 | F6: =COUNTIFS(Backlog!$E$2:$E$101,D6,Backlog!$AC$2:$AC$101,"Published") -> 0 | H6: Low | I6: =COUNTIF(Backlog!$L$2:$L$101,H6) -> 2 | K6: Fresh (<4y) | L6: =COUNTIF(Backlog!$M$2:$M$101,K6) -> 9
A7: Rendered | B7: =COUNTIF(Backlog!$AC$2:$AC$101,A7) -> 0 | D7: Electricity & Magnetism | E7: =COUNTIF(Backlog!$E$2:$E$101,D7) -> 24 | F7: =COUNTIFS(Backlog!$E$2:$E$101,D7,Backlog!$AC$2:$AC$101,"Published") -> 0 | H7: No comparable video | I7: =COUNTIF(Backlog!$L$2:$L$101,H7) -> 0 | K7: - | L7: =COUNTIF(Backlog!$M$2:$M$101,K7) -> 3
A8: Published | B8: =COUNTIF(Backlog!$AC$2:$AC$101,A8) -> 0 | D8: Optics | E8: =COUNTIF(Backlog!$E$2:$E$101,D8) -> 8 | F8: =COUNTIFS(Backlog!$E$2:$E$101,D8,Backlog!$AC$2:$AC$101,"Published") -> 0
A9: Total | B9: =SUM(B4:B8) -> 100 | D9: Modern Physics (relativity, quantum, nuclear) | E9: =COUNTIF(Backlog!$E$2:$E$101,D9) -> 10 | F9: =COUNTIFS(Backlog!$E$2:$E$101,D9,Backlog!$AC$2:$AC$101,"Published") -> 0
D10: Maths methods for physics | E10: =COUNTIF(Backlog!$E$2:$E$101,D10) -> 6 | F10: =COUNTIFS(Backlog!$E$2:$E$101,D10,Backlog!$AC$2:$AC$101,"Published") -> 0
D11: Cross-course | E11: =COUNTIF(Backlog!$E$2:$E$101,D11) -> 4 | F11: =COUNTIFS(Backlog!$E$2:$E$101,D11,Backlog!$AC$2:$AC$101,"Published") -> 0
A12: Next up (first 5 not yet published)
A13: =IFERROR(INDEX(Backlog!$D$2:$D$101,MATCH(1,Backlog!$AF$2:$AF$101,0)),"") -> ME-01 | B13: =IFERROR(INDEX(Backlog!$G$2:$G$101,MATCH(1,Backlog!$AF$2:$AF$101,0)),"") -> Vectors: components, dot and cross product in one animation
A14: =IFERROR(INDEX(Backlog!$D$2:$D$101,MATCH(2,Backlog!$AF$2:$AF$101,0)),"") -> EM-01 | B14: =IFERROR(INDEX(Backlog!$G$2:$G$101,MATCH(2,Backlog!$AF$2:$AF$101,0)),"") -> Coulomb's law and superposition: solving multi-charge problems
A15: =IFERROR(INDEX(Backlog!$D$2:$D$101,MATCH(3,Backlog!$AF$2:$AF$101,0)),"") -> ME-02 | B15: =IFERROR(INDEX(Backlog!$G$2:$G$101,MATCH(3,Backlog!$AF$2:$AF$101,0)),"") -> The kinematic equations: where they come from (not just how to use them)
A16: =IFERROR(INDEX(Backlog!$D$2:$D$101,MATCH(4,Backlog!$AF$2:$AF$101,0)),"") -> EM-02 | B16: =IFERROR(INDEX(Backlog!$G$2:$G$101,MATCH(4,Backlog!$AF$2:$AF$101,0)),"") -> The electric field: what it is, and the field of a line and a ring of charge
A17: =IFERROR(INDEX(Backlog!$D$2:$D$101,MATCH(5,Backlog!$AF$2:$AF$101,0)),"") -> ME-03 | B17: =IFERROR(INDEX(Backlog!$G$2:$G$101,MATCH(5,Backlog!$AF$2:$AF$101,0)),"") -> Free fall and the velocity-time graph, visualised
